Workbook
Name 고시항목명칭1: IFERROR(VLOOKUP(IFERROR(VLOOKUP('상품 업로드양식'!$K1,참조_표준카테고리!$A$3:$D$2527,4,FALSE),""),참조_상품고시항목!#REF!,4,FALSE),"")
Name 고시항목명칭1: IFERROR(VLOOKUP(IFERROR(VLOOKUP(#REF!,참조_표준카테고리!$A$3:$D$2527,4,FALSE),""),참조_상품고시항목!#REF!,4,FALSE),"")
Name 고시항목명칭1: IFERROR(VLOOKUP(IFERROR(VLOOKUP(#REF!,참조_표준카테고리!$A$3:$D$2527,4,FALSE),""),참조_상품고시항목!#REF!,4,FALSE),"")
Name 과면세구분: OFFSET(공통코드수식용!#REF!,0,0,MAX(IF(공통코드수식용!#REF!<>"",ROW(공통코드수식용!#REF!)))-1,1)
Name 과면세구분: OFFSET(공통코드수식용!#REF!,0,0,MAX(IF(공통코드수식용!#REF!<>"",ROW(공통코드수식용!#REF!)))-1,1)
Name 과면세구분: OFFSET(공통코드수식용!#REF!,0,0,MAX(IF(공통코드수식용!#REF!<>"",ROW(공통코드수식용!#REF!)))-1,1)
Name 구입자나이제한: OFFSET(공통코드수식용!#REF!,0,0,MAX(IF(공통코드수식용!#REF!<>"",ROW(공통코드수식용!#REF!)))-1,1)
Name 구입자나이제한: OFFSET(공통코드수식용!#REF!,0,0,MAX(IF(공통코드수식용!#REF!<>"",ROW(공통코드수식용!#REF!)))-1,1)
Name 구입자나이제한: OFFSET(공통코드수식용!#REF!,0,0,MAX(IF(공통코드수식용!#REF!<>"",ROW(공통코드수식용!#REF!)))-1,1)
Name 배송가능지역: OFFSET(공통코드수식용!#REF!,0,0,MAX(IF(공통코드수식용!#REF!<>"",ROW(공통코드수식용!#REF!)))-1,1)
Name 배송가능지역: OFFSET(공통코드수식용!#REF!,0,0,MAX(IF(공통코드수식용!#REF!<>"",ROW(공통코드수식용!#REF!)))-1,1)
Name 배송가능지역: OFFSET(공통코드수식용!#REF!,0,0,MAX(IF(공통코드수식용!#REF!<>"",ROW(공통코드수식용!#REF!)))-1,1)
Name 브랜드번호: OFFSET(참조_매입처!#REF!,0,0,MAX(IF(참조_매입처!$A$3:$A$9989<>"",ROW(참조_매입처!$A$3:$A$9989)))-2,1)
Name 브랜드번호: OFFSET(참조_제조사!#REF!,0,0,MAX(IF(참조_제조사!$A$3:$A$9999<>"",ROW(참조_제조사!$A$3:$A$9999)))-2,1)
Name 브랜드번호: OFFSET(참조_브랜드!#REF!,0,0,MAX(IF(참조_브랜드!$A$3:$A$9973<>"",ROW(참조_브랜드!$A$3:$A$9973)))-2,1)
Name 사이즈가이드등록방법코드: OFFSET(공통코드수식용!$J$2,0,0,MAX(IF(공통코드수식용!$J$2:$J$10000<>"",ROW(공통코드수식용!$J$2:$J$10000)))-1,1)
Name 사이즈가이드코드: OFFSET(공통코드수식용!$K$2,0,0,MAX(IF(공통코드수식용!$K$2:$K$10000<>"",ROW(공통코드수식용!$K$2:$K$10000)))-1,1)
Name 안전인증구분: OFFSET(공통코드수식용!#REF!,0,0,MAX(IF(공통코드수식용!#REF!<>"",ROW(공통코드수식용!#REF!)))-1,1)
Name 안전인증구분: OFFSET(공통코드수식용!#REF!,0,0,MAX(IF(공통코드수식용!#REF!<>"",ROW(공통코드수식용!#REF!)))-1,1)
Name 안전인증구분: OFFSET(공통코드수식용!#REF!,0,0,MAX(IF(공통코드수식용!#REF!<>"",ROW(공통코드수식용!#REF!)))-1,1)
Name 안전인증대상여부: IF(VLOOKUP(#REF!,참조_표준카테고리!$A$3:$C$4416,3,FALSE)="Y",OFFSET(공통코드수식용!$L$2:$L$10000,0,0,1,1),OFFSET(공통코드수식용!$L$2:$L$10000,0,0,MAX(IF(공통코드수식용!$L$2:$L$10000<>"",ROW(공통코드수식용!$L$2:$L$10000)))-1,1))
Name 안전인증대상여부: IF(VLOOKUP(#REF!,참조_표준카테고리!$A$3:$C$4416,3,FALSE)="Y",OFFSET(공통코드수식용!$L$2:$L$10000,0,0,1,1),OFFSET(공통코드수식용!$L$2:$L$10000,0,0,MAX(IF(공통코드수식용!$L$2:$L$10000<>"",ROW(공통코드수식용!$L$2:$L$10000)))-1,1))
Name 예약종료후판매방식: OFFSET(공통코드수식용!#REF!,0,0,MAX(IF(공통코드수식용!#REF!<>"",ROW(공통코드수식용!#REF!)))-1,1)
Name 예약종료후판매방식: OFFSET(공통코드수식용!#REF!,0,0,MAX(IF(공통코드수식용!#REF!<>"",ROW(공통코드수식용!#REF!)))-1,1)
Name 예약종료후판매방식: OFFSET(공통코드수식용!#REF!,0,0,MAX(IF(공통코드수식용!#REF!<>"",ROW(공통코드수식용!#REF!)))-1,1)
Name 판매방식: OFFSET(공통코드수식용!#REF!,0,0,MAX(IF(공통코드수식용!#REF!<>"",ROW(공통코드수식용!#REF!)))-1,1)
Name 판매방식: OFFSET(공통코드수식용!#REF!,0,0,MAX(IF(공통코드수식용!#REF!<>"",ROW(공통코드수식용!#REF!)))-1,1)
Name 판매방식: OFFSET(공통코드수식용!#REF!,0,0,MAX(IF(공통코드수식용!#REF!<>"",ROW(공통코드수식용!#REF!)))-1,1)
Name 표준카테고리번호: OFFSET(참조_표준카테고리!#REF!,0,0,MAX(IF(참조_표준카테고리!$A$3:$A$3457<>"",ROW(참조_표준카테고리!$A$3:$A$3457)))-2,1)
Name 협력사명: OFFSET(참조_협력사!#REF!,0,0,MAX(IF(참조_협력사!$A$3:$A$9978<>"",ROW(참조_협력사!$A$3:$A$9978)))-2,1)

Sheet 상품 업로드양식
A1: [ 상품일괄등록 엑셀 작성안내 ] - 1. 상품샘플행(3행)에 입력에 필요한 수식이 적용되어 있습니다. - 2. 신규 상품 추가 작성 시, 상품샘플행(3행)을 복사하여 작성합니다. - 3. 해당 컬럼의 입력필수 여부는 해더의 색상으로 표시 되어 있습니다. a. 노란색 : 필수 입력 항목 b. 흰색 : 선택 입력 항목 c. 회색 : 수식에 의한 자동 입력 항목(수식이 있으므로 수정하지 않습니다.) d. 분홍색 : 선택적 필수 입력 항목 - 4. 엑셀의 상품 업로드양식 시트를 제외한 시트에는 입력 수식에 필요한 기본데이터가 들어있습니다. 상품 업로드양식 시트 외의 다른 시트 수정 시 오류가 발생합니다. - 5. 일시,일자를 입력하는 컬럼의 경우 하단에 나와있는 포멧에 맞춰 숫자로 입력합니다.
A2: 상품명 | B2: 입점사 번호 | C2: 입점사명 | D2: 표준카테고리 번호 | E2: 표준카테고리명 | F2: 입점사 상품코드 | G2: 상품유형 (PR002) | H2: 상품유형명 | I2: 판매방식 (PR003) | J2: 판매방식명 | K2: 예약주문 가능 시작일시 (yyyymmddhhmm) | L2: 예약주문 가능 종료일시 (yyyymmddhhmm) | M2: 예약종료후 판매방식 (PR011) | N2: 예약상품 출고지시일 (yyyymmdd) | O2: 브랜드 번호 | P2: 브랜드명 | Q2: 매입처번호 | R2: 매입처명 | S2: 제조사 번호 | T2: 제조사명 | U2: 판매시작일자 (yyyymmdd) | V2: 판매종료일자 (yyyymmdd) | W2: 구입자 나이제한 (PR004) | X2: 전시여부 | Y2: 검색키워드 사용여부 | Z2: 검색키워드 | AA2: 포인트 적립 가능여부 | AB2: 선물하기 가능여부 | AC2: 학년(PR060) | AD2: 과목(PR061) | AE2: 규격-가로 | AF2: 규격-세로 | AG2: 규격-높이 | AH2: 규격-무게 | AI2: 규격-용량 | AJ2: 사이즈가이드 사용여부 | AK2: 사이즈가이드 등록방법코드 (PR023) | AL2: 사이즈가이드 코드 (PR024) | AM2: 사이즈가이드 내용 | AN2: 매입형태코드 (PR006) | AO2: 매입형태 | AP2: 과/면세구분 (PR007) | AQ2: 공급원가 (직접입력) | AR2: 공급원가 (마진율 계산) | AS2: 정상가 | AT2: 판매가 | AU2: 마진율 | AV2: 카테고리 수수료율 적용 여부 | AW2: 판매가 동일 적용 여부 | AX2: 업체가A | AY2: 업체가B | AZ2: 배송처리유형코드 (PR008) | BA2: 배송처리유형 | BB2: 배송상품구분 (PR010) | BC2: 배송상품구분 상세 (PR051) | BD2: 배송기일(PR025) | BE2: 배송기일사유 | BF2: 재고 관리여부 | BG2: 안전재고 알림여부 | BH2: 구매수량 제한여부 | BI2: 최소 구매수량 | BJ2: 최대 구매수량 | BK2: 옵션사용여부 | BL2: 옵션구분 (PR062) | BM2: 옵션분류명 | BN2: 옵션유형(PR019) | BO2: 옵션값 | BP2: 상품상세 | BQ2: 상품고시 품목코드 | BR2: 상품고시 품목명 | BS2: 고시항목명칭1 | BT2: 고시항목내용1 | BU2: 고시항목명칭2 | BV2: 고시항목내용2 | BW2: 고시항목명칭3 | BX2: 고시항목내용3 | BY2: 고시항목명칭4 | BZ2: 고시항목내용4 | CA2: 고시항목명칭5 | CB2: 고시항목내용5 | CC2: 고시항목명칭6 | CD2: 고시항목내용6 | CE2: 고시항목명칭7 | CF2: 고시항목내용7 | CG2: 고시항목명칭8 | CH2: 고시항목내용8 | CI2: 고시항목명칭9 | CJ2: 고시항목내용9 | CK2: 고시항목명칭10 | CL2: 고시항목내용10 | CM2: 고시항목명칭11 | CN2: 고시항목내용11 | CO2: 고시항목명칭12 | CP2: 고시항목내용12 | CQ2: 고시항목명칭13 | CR2: 고시항목내용13 | CS2: 고시항목명칭14 | CT2: 고시항목내용14 | CU2: 안전인증 대상여부 | CV2: 안전인증구분1 (PR026) | CW2: 안전인증기관명1 | CX2: 안전인증분야1-1 | CY2: 안전인증분야1-2 | CZ2: 안전인증번호1 | DA2: 안전인증 적용시작일자1 (yyyymmdd) | DB2: 안전인증 적용종료일자1 (yyyymmdd) | DC2: 안전인증구분2 (PR026) | DD2: 안전인증기관명2 | DE2: 안전인증분야2-1 | DF2: 안전인증분야2-2 | DG2: 안전인증번호2 | DH2: 안전인증 적용시작일자2 (yyyymmdd) | DI2: 안전인증 적용종료일자2 (yyyymmdd) | DJ2: 안전인증구분3 (PR026) | DK2: 안전인증기관명3 | DL2: 안전인증분야3-1 | DM2: 안전인증분야3-2 | DN2: 안전인증번호3 | DO2: 안전인증 적용시작일자3 (yyyymmdd) | DP2: 안전인증 적용종료일자3 (yyyymmdd) | DQ2: 안전인증구분4 (PR026) | DR2: 안전인증기관명4 | DS2: 안전인증분야4-1 | DT2: 안전인증분야4-2 | DU2: 안전인증번호4 | DV2: 안전인증 적용시작일자4 (yyyymmdd) | DW2: 안전인증 적용종료일자4 (yyyymmdd) | DX2: 안전인증구분5 (PR026) | DY2: 안전인증기관명5 | DZ2: 안전인증분야5-1 | EA2: 안전인증분야5-2 | EB2: 안전인증번호5 | EC2: 안전인증 적용시작일자5 (yyyymmdd) | ED2: 안전인증 적용종료일자5 (yyyymmdd)
A3: 상품샘플 | B3: =IFERROR(VLOOKUP(C3,참조_협력사!$A$3:$B$10000,2,FALSE),"") | C3: 아이스크림미디어 | D3: BC03010000 | E3: =IFERROR(VLOOKUP(D3,참조_표준카테고리!$A$3:$B$10000,2,FALSE),"") | F3: 1000001 | G3: 10 | H3: {=IFERROR(INDEX(참조_공통코드!$C$3:$C$200,MATCH(1,(참조_공통코드!$A$3:$A$200=공통코드수식용!$A$1)*(참조_공통코드!$B$3:$B$200=$G3),0),0),"")} | I3: 10 | J3: {=IFERROR(INDEX(참조_공통코드!$C$3:$C$200,MATCH(1,(참조_공통코드!$A$3:$A$200=공통코드수식용!$B$1)*(참조_공통코드!$B$3:$B$200=$I3),0),0),"")} | K3: 202312200000 | L3: 202312200000 | M3: 01 | N3: 20241220 | O3: 10000 | P3: =IFERROR(VLOOKUP(O3,참조_브랜드!$A$3:$B$10000,2,FALSE),"") | Q3: 1 | R3: =IFERROR(VLOOKUP(Q3,참조_매입처!$A$3:$B$10000,2,FALSE),"") | S3: 1 | T3: =IFERROR(VLOOKUP(S3,참조_제조사!$A$3:$B$10000,2,FALSE),"") | U3: 20240901 | V3: 20501231 | W3: 0 | X3: Y | Y3: Y | Z3: 사과,당근,토마토 | AA3: Y | AB3: Y | AC3: 10,11,12,13,14,15,16,17,18,19 | AD3: 10 | AE3: 100 | AF3: 200 | AG3: 300 | AH3: 400 | AI3: =IF(OR(ISBLANK($AE3),ISBLANK($AF3),ISBLANK($AG3)),"",IF(OR(ISNUMBER($AE3),ISNUMBER($AF3),ISNUMBER($AG3)),IFERROR(ROUND(($AE3*$AF3*$AG3)/1000000,3),""),"")) -> 6 | AJ3: Y | AK3: 10 | AL3: 10 | AN3: =IFERROR(VLOOKUP(C3,참조_협력사!$A$3:$C$10000,3,FALSE),"") | AO3: =IFERROR(VLOOKUP(C3,참조_협력사!$A$3:$D$10000,4,FALSE),"") | AP3: 01 | AR3: =IFERROR(IF($AV3="Y",IF(AND(ISNUMBER(--IFERROR(TRIM($AT3),"")),ISNUMBER(--IFERROR(TRIM($AU3),"")),--IFERROR(TRIM($AU3),0)>=0,--IFERROR(TRIM($AU3),0)<=100),TRUNC(--IFERROR(TRIM($AT3),0) * (1 - --IFERROR(TRIM($AU3),0)/100)),""),""),"") | AU3: =IF($AV3="N",IF(AND(ISNUMBER(VALUE($AQ3)),ISNUMBER(VALUE($AT3)),VALUE($AQ3)<>0,VALUE($AT3)<>0),ROUND(((VALUE($AT3)-VALUE($AQ3))/VALUE($AT3))*100,2),""),IF($AV3="Y",IFERROR(VLOOKUP(D3,참조_표준카테고리!$A$3:$E$10000,5,FALSE),""),"")) | AV3: N | AW3: N | AX3: =IFERROR(IF($AW3="N",IF(AND(ISNUMBER(VALUE($AU3)),ISNUMBER(VALUE($AT3)),VALUE($AT3)<>0),ROUND(IF($AU3<25,$AT3,IF($AU3<30,$AT3*0.9,IF($AU3<40,$AT3*0.8,IF($AU3<50,$AT3*0.75,IF($AU3<60,$AT3*0.7,$AT3*0.65)))))/10,0)*10,""),$AT3),"") | AY3: =IFERROR(IF($AW3="N",IF(AND(ISNUMBER(VALUE($AU3)),ISNUMBER(VALUE($AT3)),VALUE($AT3)<>0),ROUND(IF($AU3<25,$AT3,IF($AU3<30,$AT3*0.95,IF($AU3<40,$AT3*0.9,IF($AU3<50,$AT3*0.85,IF($AU3<60,$AT3*0.85,$AT3*0.85)))))/10,0)*10,""),$AT3),"") | AZ3: =IFERROR(VLOOKUP(C3,참조_협력사!$A$3:$E$10000,5,FALSE),"") | BA3: =IFERROR(VLOOKUP(C3,참조_협력사!$A$3:$F$10000,6,FALSE),"") | BB3: 01 | BC3: 10 | BD3: 0 | BF3: Y | BG3: Y | BH3: Y | BK3: Y | BL3: 10 10 20 | BM3: 색상 사이즈 사이즈 | BN3: 10 11 11 | BO3: 빨강,노랑,파랑 S,M S,M,L | BP3: <p>상품상세</p> | BQ3: =IFERROR(VLOOKUP(D3,참조_표준카테고리!$A$3:$D$10000,4,FALSE),"") | BR3: =IFERROR(VLOOKUP(IFERROR(VLOOKUP($D3,참조_표준카테고리!$A$3:$D$10000,4,FALSE),""),참조_상품고시항목!$A$3:$AD$42,2,FALSE),"") | BS3: =IFERROR(VLOOKUP(IFERROR(VLOOKUP($D3,참조_표준카테고리!$A$3:$D$10000,4,FALSE),""),참조_상품고시항목!$A$3:$AD$42,4,FALSE),"") | BU3: =IFERROR(VLOOKUP(IFERROR(VLOOKUP($D3,참조_표준카테고리!$A$3:$D$10000,4,FALSE),""),참조_상품고시항목!$A$3:$AD$42,6,FALSE),"") | BW3: =IFERROR(VLOOKUP(IFERROR(VLOOKUP($D3,참조_표준카테고리!$A$3:$D$10000,4,FALSE),""),참조_상품고시항목!$A$3:$AD$42,8,FALSE),"") | BY3: =IFERROR(VLOOKUP(IFERROR(VLOOKUP($D3,참조_표준카테고리!$A$3:$D$10000,4,FALSE),""),참조_상품고시항목!$A$3:$AD$42,10,FALSE),"") | CA3: =IFERROR(VLOOKUP(IFERROR(VLOOKUP($D3,참조_표준카테고리!$A$3:$D$10000,4,FALSE),""),참조_상품고시항목!$A$3:$AD$42,12,FALSE),"") | CC3: =IFERROR(VLOOKUP(IFERROR(VLOOKUP($D3,참조_표준카테고리!$A$3:$D$10000,4,FALSE),""),참조_상품고시항목!$A$3:$AD$42,14,FALSE),"") | CE3: =IFERROR(VLOOKUP(IFERROR(VLOOKUP($D3,참조_표준카테고리!$A$3:$D$10000,4,FALSE),""),참조_상품고시항목!$A$3:$AD$42,16,FALSE),"") | CG3: =IFERROR(VLOOKUP(IFERROR(VLOOKUP($D3,참조_표준카테고리!$A$3:$D$10000,4,FALSE),""),참조_상품고시항목!$A$3:$AD$42,18,FALSE),"") | CI3: =IFERROR(VLOOKUP(IFERROR(VLOOKUP($D3,참조_표준카테고리!$A$3:$D$10000,4,FALSE),""),참조_상품고시항목!$A$3:$AD$42,20,FALSE),"") | CK3: =IFERROR(VLOOKUP(IFERROR(VLOOKUP($D3,참조_표준카테고리!$A$3:$D$10000,4,FALSE),""),참조_상품고시항목!$A$3:$AD$42,22,FALSE),"") | CM3: =IFERROR(VLOOKUP(IFERROR(VLOOKUP($D3,참조_표준카테고리!$A$3:$D$10000,4,FALSE),""),참조_상품고시항목!$A$3:$AD$42,24,FALSE),"") | CO3: =IFERROR(VLOOKUP(IFERROR(VLOOKUP($D3,참조_표준카테고리!$A$3:$D$10000,4,FALSE),""),참조_상품고시항목!$A$3:$AD$42,26,FALSE),"") | CQ3: =IFERROR(VLOOKUP(IFERROR(VLOOKUP($D3,참조_표준카테고리!$A$3:$D$10000,4,FALSE),""),참조_상품고시항목!$A$3:$AD$42,28,FALSE),"") | CS3: =IFERROR(VLOOKUP(IFERROR(VLOOKUP($D3,참조_표준카테고리!$A$3:$D$10000,4,FALSE),""),참조_상품고시항목!$A$3:$AD$42,30,FALSE),"") | CU3: Y | CV3: 17 | CW3: 한국화학융합시험연구원(KTR) | CX3: 어린이제품 | CY3: 안전확인 | CZ3: CB000H000-000055 | DA3: 20231110 | DB3: 20231231

Sheet 참조_공통코드
A1: ■ 공통코드 정보
A2: 그룹코드 번호 | B2: 코드 번호 | C2: 코드 명
A3: PR002 | B3: 10 | C3: 일반상품
A4: PR002 | B4: 30 | C4: e-쿠폰상품
A5: PR003 | B5: 10 | C5: 일반판매
A6: PR003 | B6: 20 | C6: 예약상품
A7: PR004 | B7: 0 | C7: 0
A8: PR004 | B8: 15 | C8: 15
A9: PR004 | B9: 19 | C9: 19
A10: PR006 | B10: 10 | C10: PB
A11: PR006 | B11: 20 | C11: 입점사
A12: PR006 | B12: 40 | C12: 중계
A13: PR007 | B13: 01 | C13: 과세
... A111: ST015 | B111: 10 | C111: V2

Sheet 참조_협력사
A1: ■ 협력사 정보
A2: 협력사 명 | B2: 협력사 번호 | C2: 매입형태코드 | D2: 매입형태명 | E2: 배송처리유형코드 | F2: 배송처리유형명 | G2: 마진율구분코드 | H2: 마진율구분명 | I2: 마진율1 | J2: 마진율2 | K2: 사업자종류코드 | L2: 사업자종류명
A3: 주식회사 거영I&D | B3: 1482 | C3: 20 | D3: 입점사 | E3: 20 | F3: 업체배송 | I3: 0.0 | J3: 0.0 | K3: 20 | L3: 일반과세자

Sheet 참조_표준카테고리
A1: ■ 표준 리프 카테고리 정보
A2: 리프표준카테고리코드 | B2: 표준카테고리 Depth 표시 | C2: 안전인증대상여부 | D2: 고시품목코드 | E2: 마진율
A3: BC0217070100 | B3: 하이스토어>학습환경>계절가전>가습기 | C3: N | D3: 012 | E3: 12
A4: BC0217070200 | B4: 하이스토어>학습환경>계절가전>제습기/공기청정기 | C4: N | D4: 012 | E4: 10
A5: BC0217070300 | B5: 하이스토어>학습환경>계절가전>선풍기/서큘레이터 | C5: N | D5: 012 | E5: 12
A6: BC0217070400 | B6: 하이스토어>학습환경>계절가전>난로/매트 | C6: N | D6: 012 | E6: 12
A7: BC0217070500 | B7: 하이스토어>학습환경>계절가전>모기퇴치기 | C7: Y | D7: 040 | E7: 12
A8: BC0217060100 | B8: 하이스토어>학습환경>생활가전>고데기/드라이기 | C8: N | D8: 012 | E8: 12
A9: BC0217060200 | B9: 하이스토어>학습환경>생활가전>구강세정기/칫솔살균기 | C9: N | D9: 012 | E9: 12
A10: BC0217060300 | B10: 하이스토어>학습환경>생활가전>청소기 | C10: N | D10: 012 | E10: 12
A11: BC0217060400 | B11: 하이스토어>학습환경>생활가전>안마기/찜질기/자세교정 | C11: N | D11: 012 | E11: 12
A12: BC0217050100 | B12: 하이스토어>학습환경>음향기기>이어폰 | C12: N | D12: 012 | E12: 12
A13: BC0217050200 | B13: 하이스토어>학습환경>음향기기>헤드셋/스피커 | C13: N | D13: 012 | E13: 8
A14: BC0217040100 | B14: 하이스토어>학습환경>디지털기기>노트북/태블릿 | C14: N | D14: 012 | E14: 8
... A87: BC0216240102 | B87: 하이스토어>교과서/도서>유아>100세 그림책 | C87: N | D87: 026 | E87: 0
A88: BC0216240101 | B88: 하이스토어>교과서/도서>유아>100세 그림책 | E88: 0
A89: BC0216230710 | B89: 하이스토어>교과서/도서>역사>한국사/한국문화 | C89: N | D89: 026 | E89: 0
A90: BC0216230709 | B90: 하이스토어>교과서/도서>역사>한국사/한국문화 | C90: N | D90: 026 | E90: 0
A91: BC0216230708 | B91: 하이스토어>교과서/도서>역사>한국사/한국문화 | C91: N | D91: 026 | E91: 0
A92: BC0216230707 | B92: 하이스토어>교과서/도서>역사>한국사/한국문화 | C92: N | D92: 026 | E92: 0
A93: BC0216230706 | B93: 하이스토어>교과서/도서>역사>한국사/한국문화 | C93: N | D93: 026 | E93: 0
A94: BC0216230705 | B94: 하이스토어>교과서/도서>역사>한국사/한국문화 | C94: N | D94: 026 | E94: 0
A95: BC0216230704 | B95: 하이스토어>교과서/도서>역사>한국사/한국문화 | C95: N | D95: 026 | E95: 0
A96: BC0216230703 | B96: 하이스토어>교과서/도서>역사>한국사/한국문화 | C96: N | D96: 026 | E96: 0
A97: BC0216230702 | B97: 하이스토어>교과서/도서>역사>한국사/한국문화 | C97: N | D97: 026 | E97: 0
A98: BC0216230701 | B98: 하이스토어>교과서/도서>역사>한국사/한국문화 | C98: N | D98: 026 | E98: 0
A99: BC0216230603 | B99: 하이스토어>교과서/도서>역사>동양사/동양문화 | C99: N | D99: 026 | E99: 0
A100: BC0216230602 | B100: 하이스토어>교과서/도서>역사>동양사/동양문화 | C100: N | D100: 026 | E100: 0
... A252: BC0216170711 | B252: 하이스토어>교과서/도서>어린이>어린이 교양 | C252: N | D252: 026 | E252: 0
A253: BC0216170514 | B253: 하이스토어>교과서/도서>어린이>1-2학년 | E253: 0
A254: BC0216170513 | B254: 하이스토어>교과서/도서>어린이>1-2학년 | C254: N | D254: 026 | E254: 0
A255: BC0216170512 | B255: 하이스토어>교과서/도서>어린이>1-2학년 | C255: N | D255: 026 | E255: 0
A256: BC0216170511 | B256: 하이스토어>교과서/도서>어린이>1-2학년 | C256: N | D256: 026 | E256: 0
A257: BC0216170510 | B257: 하이스토어>교과서/도서>어린이>1-2학년 | C257: N | D257: 026 | E257: 0
A258: BC0216170509 | B258: 하이스토어>교과서/도서>어린이>1-2학년 | E258: 0
A259: BC0216170508 | B259: 하이스토어>교과서/도서>어린이>1-2학년 | C259: N | D259: 026 | E259: 0
A260: BC0216170507 | B260: 하이스토어>교과서/도서>어린이>1-2학년 | C260: N | D260: 026 | E260: 0
A261: BC0216170506 | B261: 하이스토어>교과서/도서>어린이>1-2학년 | C261: N | D261: 026 | E261: 0
A262: BC0216170505 | B262: 하이스토어>교과서/도서>어린이>1-2학년 | C262: N | D262: 026 | E262: 0
A263: BC0216170504 | B263: 하이스토어>교과서/도서>어린이>1-2학년 | C263: N | D263: 026 | E263: 0
...

Sheet 참조_상품고시항목
A1: ■ 상품고시품목 내 항목정보
A2: 고시품목코드 | B2: 고시품목명 | C2: 고시항목1 | D2: 고시항목명1 | E2: 고시항목2 | F2: 고시항목명2 | G2: 고시항목3 | H2: 고시항목명3 | I2: 고시항목4 | J2: 고시항목명4 | K2: 고시항목5 | L2: 고시항목명5 | M2: 고시항목6 | N2: 고시항목명6 | O2: 고시항목7 | P2: 고시항목명7 | Q2: 고시항목8 | R2: 고시항목명8 | S2: 고시항목9 | T2: 고시항목명9 | U2: 고시항목10 | V2: 고시항목명10 | W2: 고시항목11 | X2: 고시항목명11 | Y2: 고시항목12 | Z2: 고시항목명12 | AA2: 고시항목13 | AB2: 고시항목명13 | AC2: 고시항목14 | AD2: 고시항목명14
A3: 001 | B3: 의류 | C3: 027 | D3: 제품 소재 | E3: 187 | F3: 색상 | G3: 034 | H3: 치수 | I3: 086 | J3: 제조자 | K3: 178 | L3: 제조국 | M3: 133 | N3: 세탁방법 및 취급시 주의사항 | O3: 032 | P3: 제조연월 | Q3: 147 | R3: 품질보증기준 | S3: 164 | T3: A/S 책임자 / 전화번호
A4: 002 | B4: 구두/신발 | C4: 173 | D4: 제품 소재 | E4: 187 | F4: 색상 | G4: 150 | H4: 치수 | I4: 086 | J4: 제조자 | K4: 178 | L4: 제조국 | M4: 121 | N4: 취급시 주의사항 | O4: 147 | P4: 품질보증기준 | Q4: 164 | R4: A/S 책임자 / 전화번호
A5: 003 | B5: 가방 | C5: 183 | D5: 종류 | E5: 023 | F5: 소재 | G5: 187 | H5: 색상 | I5: 124 | J5: 크기 | K5: 086 | L5: 제조자 | M5: 178 | N5: 제조국 | O5: 121 | P5: 취급시 주의사항 | Q5: 147 | R5: 품질보증기준 | S5: 164 | T5: A/S 책임자 / 전화번호
A6: 004 | B6: 패션잡화 (모자 / 벨트 / 액세서리) | C6: 183 | D6: 종류 | E6: 023 | F6: 소재 | G6: 034 | H6: 치수 | I6: 086 | J6: 제조자 | K6: 178 | L6: 제조국 | M6: 121 | N6: 취급시 주의사항 | O6: 147 | P6: 품질보증기준 | Q6: 164 | R6: A/S 책임자 / 전화번호
A7: 005 | B7: 침구류 / 커튼 | C7: 103 | D7: 제품소재 | E7: 187 | F7: 색상 | G7: 034 | H7: 치수 | I7: 132 | J7: 제품구성 | K7: 086 | L7: 제조자 | M7: 178 | N7: 제조국 | O7: 133 | P7: 세탁방법 및 취급시 주의사항 | Q7: 147 | R7: 품질보증기준 | S7: 164 | T7: A/S 책임자 / 전화번호
A8: 006 | B8: 가구(침대 / 소파 / 싱크대 / DIY제품) | C8: 169 | D8: 품명 | E8: 044 | F8: KC인증 필 유무 | G8: 187 | H8: 색상 | I8: 146 | J8: 구성품 | K8: 005 | L8: 주요소재 | M8: 086 | N8: 제조자 | O8: 079 | P8: 제조국 | Q8: 138 | R8: 크기 | S8: 127 | T8: 배송설치비용 | U8: 147 | V8: 품질보증기준 | W8: 164 | X8: A/S 책임자 / 전화번호
A9: 007 | B9: 영상가전(TV류) | C9: 174 | D9: 품명 및 모델명 | E9: 111 | F9: KC인증 필 유무 | G9: 181 | H9: 정격전압, 소비전력 | I9: 080 | J9: 에너지소비효율등급 | K9: 170 | L9: 동일모델의 출시년월 | M9: 086 | N9: 제조자 | O9: 178 | P9: 제조국 | Q9: 155 | R9: 크기(용량, 형태 포함) | S9: 100 | T9: 화면사양 | U9: 147 | V9: 품질보증기준 | W9: 164 | X9: A/S 책임자 / 전화번호
A10: 008 | B10: 가정용 전기제품(냉장고 / 세탁기 / 식기세척기 / 전자레인지) | C10: 174 | D10: 품명 및 모델명 | E10: 111 | F10: KC인증 필 유무 | G10: 181 | H10: 정격전압, 소비전력 | I10: 080 | J10: 에너지소비효율등급 | K10: 170 | L10: 동일모델의 출시년월 | M10: 086 | N10: 제조자 | O10: 178 | P10: 제조국 | Q10: 145 | R10: 크기(용량, 형태 포함) | S10: 147 | T10: 품질보증기준 | U10: 164 | V10: A/S 책임자 / 전화번호
A11: 009 | B11: 계절가전(에어컨 / 온풍기) | C11: 174 | D11: 품명 및 모델명 | E11: 111 | F11: KC인증 필 유무 | G11: 181 | H11: 정격전압, 소비전력 | I11: 080 | J11: 에너지소비효율등급 | K11: 170 | L11: 동일모델의 출시년월 | M11: 086 | N11: 제조자 | O11: 178 | P11: 제조국 | Q11: 108 | R11: 크기(형태 및 실외기 포함) | S11: 088 | T11: 냉난방면적 | U11: 017 | V11: 추가설치비용 | W11: 184 | X11: 품질보증기준 | Y11: 164 | Z11: A/S 책임자 / 전화번호
A12: 010 | B12: 사무용기기(컴퓨터 / 노트북 / 프린터) | C12: 174 | D12: 품명 및 모델명 | E12: 180 | F12: KC인증 필 유무 | G12: 181 | H12: 정격전압, 소비전력 | I12: 080 | J12: 에너지소비효율등급 | K12: 170 | L12: 동일모델의 출시년월 | M12: 086 | N12: 제조자 | O12: 178 | P12: 제조국 | Q12: 160 | R12: 크기, 무게 | S12: 177 | T12: 주요사양 | U12: 147 | V12: 품질보증기준 | W12: 164 | X12: A/S 책임자 / 전화번호
A13: 011 | B13: 광학기기(디지털카메라 / 캠코더) | C13: 174 | D13: 품명 및 모델명 | E13: 180 | F13: KC인증 필 유무 | G13: 170 | H13: 동일모델의 출시년월 | I13: 086 | J13: 제조자 | K13: 178 | L13: 제조국 | M13: 021 | N13: 크기, 무게 | O13: 102 | P13: 주요 사양 | Q13: 147 | R13: 품질보증기준 | S13: 164 | T13: A/S 책임자 / 전화번호
A14: 012 | B14: 소형전자(MP3 / 전자사전 등) | C14: 174 | D14: 품명 및 모델명 | E14: 180 | F14: KC인증 필 유무 | G14: 181 | H14: 정격전압, 소비전력 | I14: 170 | J14: 동일모델의 출시년월 | K14: 086 | L14: 제조자 | M14: 178 | N14: 제조국 | O14: 021 | P14: 크기, 무게 | Q14: 102 | R14: 주요 사양 | S14: 147 | T14: 품질보증기준 | U14: 164 | V14: A/S 책임자 / 전화번호
A15: 013 | B15: 휴대폰 | C15: 174 | D15: 품명 및 모델명 | E15: 180 | F15: KC인증 필 유무 | G15: 170 | H15: 동일모델의 출시년월 | I15: 086 | J15: 제조자 | K15: 178 | L15: 제조국 | M15: 021 | N15: 크기, 무게 | O15: 026 | P15: 이동통신 가입조건 | Q15: 102 | R15: 주요 사양 | S15: 147 | T15: 품질보증기준 | U15: 164 | V15: A/S 책임자 / 전화번호
A16: 014 | B16: 내비게이션 | C16: 174 | D16: 품명 및 모델명 | E16: 180 | F16: KC인증 필 유무 | G16: 181 | H16: 정격전압, 소비전력 | I16: 170 | J16: 동일모델의 출시년월 | K16: 086 | L16: 제조자 | M16: 178 | N16: 제조국 | O16: 021 | P16: 크기, 무게 | Q16: 102 | R16: 주요 사양 | S16: 153 | T16: 맵 업데이트 비용 및 무상기간 | U16: 147 | V16: 품질보증기준 | W16: 164 | X16: A/S 책임자 / 전화번호
A17: 015 | B17: 자동차용품 (자동차부품 / 기타 자동차용품) | C17: 174 | D17: 품명 및 모델명 | E17: 170 | F17: 동일모델의 출시년월 | G17: 107 | H17: KC인증 필 유무 | I17: 086 | J17: 제조자 | K17: 178 | L17: 제조국 | M17: 124 | N17: 크기 | O17: 020 | P17: 적용차종 | Q17: 172 | R17: 제품사용으로 인한 위험 및 유의사항 | S17: 147 | T17: 품질보증기준 | U17: 190 | V17: 검사합격증 번호 | W17: 164 | X17: A/S 책임자 / 전화번호
A18: 016 | B18: 의료기기 | C18: 174 | D18: 품명 및 모델명 | E18: 101 | F18: 의료기기법상 허가신고 번호 | G18: 001 | H18: 정격전압, 소비전력 | I18: 170 | J18: 동일모델의 출시년월 | K18: 086 | L18: 제조자 | M18: 178 | N18: 제조국 | O18: 120 | P18: 제품의 사용목적 및 사용방법 | Q18: 121 | R18: 취급시 주의사항 | S18: 147 | T18: 품질보증기준 | U18: 164 | V18: A/S 책임자 / 전화번호
A19: 017 | B19: 주방용품 | C19: 174 | D19: 품명 및 모델명 | E19: 065 | F19: 재질 | G19: 146 | H19: 구성품 | I19: 124 | J19: 크기 | K19: 170 | L19: 동일모델의 출시년월 | M19: 086 | N19: 제조자 | O19: 178 | P19: 제조국 | Q19: 158 | R19: 식품위생법상 수입 기구용품 여부 | S19: 147 | T19: 품질보증기준 | U19: 164 | V19: A/S 책임자 / 전화번호
A20: 018 | B20: 화장품 | C20: 185 | D20: 용량 또는 중량 | E20: 098 | F20: 제품 주요 사양 | G20: 141 | H20: 사용기한(개봉 후 사용기간) | I20: 066 | J20: 사용방법 | K20: 052 | L20: 제조자 및 제조판매업자 | M20: 178 | N20: 제조국 | O20: 007 | P20: 주요성분 | Q20: 129 | R20: 기능성 화장품 식품의약품안전처 심사필 여부 | S20: 095 | T20: 사용시 주의사항 | U20: 147 | V20: 품질보증기준 | W20: 064 | X20: 소비자상담 전화번호
A21: 019 | B21: 귀금속 / 보석 / 시계류 | C21: 049 | D21: 소재/순도/밴드재질(시계) | E21: 130 | F21: 중량 | G21: 086 | H21: 제조자 | I21: 070 | J21: 제조국 | K21: 034 | L21: 치수 | M21: 091 | N21: 착용시 주의사항 | O21: 167 | P21: 주요 사양 | Q21: 031 | R21: 보증서 제공여부 | S21: 147 | T21: 품질보증기준 | U21: 164 | V21: A/S 책임자 / 전화번호
A22: 020 | B22: 식품(농수축산물) | C22: 115 | D22: 품목 또는 명칭 | E22: 016 | F22: 용량(중량),수량,크기 | G22: 071 | H22: 생산자(수입자) | I22: 067 | J22: 원산지 | K22: 004 | L22: 제조연월일(포장일 또는 생산연도) | M22: 099 | N22: 관련법상 표시사항 | O22: 140 | P22: 상품구성 | Q22: 085 | R22: 보관방법 또는 취급방법 | S22: 036 | T22: 주의사항 | U22: 073 | V22: 소비자상담관련 전화번호
A23: 021 | B23: 가공식품 | C23: 061 | D23: 제품명 | E23: 082 | F23: 식품의 유형 | G23: 188 | H23: 생산자(제조원) 및 소재지 | I23: 078 | J23: 제조연월일(유통기한) | K23: 148 | L23: 용량(중량), 수량 | M23: 048 | N23: 원재료명 및 함량 | O23: 144 | P23: 영양성분 | Q23: 077 | R23: 유전자 재조합 식품 여부 | S23: 069 | T23: 주의사항 | U23: 096 | V23: 수입식품여부 | W23: 064 | X23: 소비자상담 전화번호
A24: 022 | B24: 건강기능식품 | C24: 061 | D24: 제품명 | E24: 082 | F24: 식품의 유형 | G24: 046 | H24: 생산자(제조원) 및 소재지 | I24: 019 | J24: 제조연월일(유통기한) | K24: 148 | L24: 용량(중량), 수량 | M24: 048 | N24: 원재료명 및 함량 | O24: 189 | P24: 영양정보 | Q24: 029 | R24: 기능정보 | S24: 054 | T24: 섭취량, 섭취방법 및 주의사항 | U24: 093 | V24: 질병 예방, 치료 의약품 아님 명시 | W24: 128 | X24: 유전자 재조합 식품 여부 | Y24: 096 | Z24: 수입식품여부 | AA24: 069 | AB24: 주의사항 | AC24: 064
A25: 023 | B25: 영유아용품 | C25: 174 | D25: 품명 및 모델명 | E25: 072 | F25: KC인증 필 유무 | G25: 165 | H25: 크기, 중량 | I25: 187 | J25: 색상 | K25: 057 | L25: 재질 | M25: 028 | N25: 사용연령(체중범위) | O25: 170 | P25: 동일모델의 출시년월 | Q25: 086 | R25: 제조자 | S25: 178 | T25: 제조국 | U25: 154 | V25: 취급방법 및 주의사항 | W25: 184 | X25: 품질보증기준 | Y25: 164 | Z25: A/S 책임자 / 전화번호
A26: 024 | B26: 악기 | C26: 174 | D26: 품명 및 모델명 | E26: 124 | F26: 크기 | G26: 187 | H26: 색상 | I26: 065 | J26: 재질 | K26: 132 | L26: 제품구성 | M26: 170 | N26: 동일모델의 출시년월 | O26: 086 | P26: 제조자 | Q26: 178 | R26: 제조국 | S26: 137 | T26: 상품별 세부 사양 | U26: 147 | V26: 품질보증기준 | W26: 164 | X26: A/S 책임자 / 전화번호
A27: 025 | B27: 스포츠용품 | C27: 174 | D27: 품명 및 모델명 | E27: 165 | F27: 크기, 중량 | G27: 187 | H27: 색상 | I27: 065 | J27: 재질 | K27: 012 | L27: 제품 구성 | M27: 170 | N27: 동일모델의 출시년월 | O27: 086 | P27: 제조자 | Q27: 178 | R27: 제조국 | S27: 137 | T27: 상품별 세부 사양 | U27: 147 | V27: 품질보증기준 | W27: 164 | X27: A/S 책임자 / 전화번호
A28: 026 | B28: 서적 | C28: 039 | D28: 도서명 | E28: 089 | F28: 저자, 출판사 | G28: 125 | H28: 크기 | I28: 142 | J28: 쪽수 | K28: 058 | L28: 제품 구성 | M28: 002 | N28: 출간일 | O28: 009 | P28: 목차 또는 책소개
A29: 027 | B29: 호텔 / 펜션 예약 | C29: 106 | D29: 국가 또는 지역명 | E29: 182 | F29: 숙소형태 | G29: 179 | H29: 등급, 객실타입 | I29: 135 | J29: 사용가능 인원, 인원 추가 시 비용 | K29: 041 | L29: 부대시설, 제공 서비스(조식등) | M29: 076 | N29: 취소 규정(환불,위약금등) | O29: 105 | P29: 예약담당 연락처
A30: 028 | B30: 여행패키지 | C30: 022 | D30: 여행사 | E30: 025 | F30: 이용항공편 | G30: 176 | H30: 여행기간 및 일정 | I30: 090 | J30: 총 예정 인원, 출발 가능 인원 | K30: 011 | L30: 숙박정보 | M30: 051 | N30: 여행상품 가격 | O30: 186 | P30: 선택경비 유무 | Q30: 175 | R30: 선택관광 및 대체일정 | S30: 075 | T30: 가이드 팁 | U30: 076 | V30: 취소 규정(환불,위약금등) | W30: 087 | X30: 해외여행의 경우 외교부가 지정하는 여행경보단계 | Y30: 105 | Z30: 예약담당 연락처
A31: 029 | B31: 항공권 | C31: 018 | D31: 요금조건, 왕복편도 여부 | E31: 122 | F31: 유효기간 | G31: 156 | H31: 제한사항 | I31: 003 | J31: 티켓수령방법 | K31: 008 | L31: 좌석종류 | M31: 118 | N31: 가격에 포함되지 않은 내역 및 금액 | O31: 152 | P31: 취소 규정 | Q31: 105 | R31: 예약담당 연락처
A32: 030 | B32: 자동차 대여 서비스 (렌터카) | C32: 074 | D32: 차종 | E32: 024 | F32: 소유권 이전 여부 | G32: 151 | H32: 소유권 이전 조건 | I32: 053 | J32: 추가 선택 시 비용 | K32: 123 | L32: 차량 반환 시 연료대금 정산 방법 | M32: 114 | N32: 차량의 고장훼손 시 소비자 책임 | O32: 040 | P32: 예약 취소 또는 중도 해약 시 환불 기준 | Q32: 073 | R32: 소비자상담관련 전화번호
A33: 031 | B33: 물품대여 서비스 (정수기, 비데, 공기청정기 등) | C33: 174 | D33: 품명 및 모델명 | E33: 117 | F33: 소유권 이전 여부 | G33: 113 | H33: 소유권 이전 조건 | I33: 038 | J33: 유지보수 조건 | K33: 159 | L33: 상품의 고장분실훼손 시 소비자 책임 | M33: 143 | N33: 중도 해약 시 환불 기준 | O33: 097 | P33: 제품 사양 | Q33: 073 | R33: 소비자상담관련 전화번호
A34: 032 | B34: 물품대여 서비스 (서적, 유아용품, 행사용품 등) | C34: 174 | D34: 품명 및 모델명 | E34: 117 | F34: 소유권 이전 조건 | G34: 159 | H34: 상품의 고장분실훼손 시 소비자 책임 | I34: 143 | J34: 중도 해약 시 환불 기준 | K34: 073 | L34: 소비자상담관련 전화번호
A35: 033 | B35: 디지털 콘텐츠 (음원, 게임, 인터넷강의 등) | C35: 094 | D35: 제작자 또는 공급자 | E35: 139 | F35: 이용조건, 이용기간 | G35: 134 | H35: 상품 제공 방식 | I35: 055 | J35: 최소 시스템 사양, 필수 소프트웨어 | K35: 015 | L35: 청약철회 또는 계약의 해제해지에 따른 효과 | M35: 073 | N35: 소비자상담관련 전화번호
A36: 034 | B36: 상품권 / 쿠폰 | C36: 157 | D36: 발행자 | E36: 166 | F36: 유효기간, 이용조건 | G36: 006 | H36: 이용 가능 매장 | I36: 033 | J36: 잔액 환급 조건 | K36: 073 | L36: 소비자상담관련 전화번호
A37: 035 | B37: 모바일 쿠폰 | C37: 157 | D37: 발행자 | E37: 110 | F37: 유효기간, 이용조건 | G37: 006 | H37: 이용 가능 매장 | I37: 116 | J37: 환불조건 및 방법 | K37: 073 | L37: 소비자상담관련 전화번호
A38: 036 | B38: 영화공연 | C38: 013 | D38: 주최 또는 기획 | E38: 068 | F38: 주연 | G38: 149 | H38: 관람등급 | I38: 081 | J38: 상영공연시간 | K38: 163 | L38: 상영공연장소 | M38: 063 | N38: 예매 취소 조건 | O38: 060 | P38: 취소/환불방법 | Q38: 073 | R38: 소비자상담관련 전화번호
A39: 037 | B39: 생활화학제품 | C39: 136 | D39: 품목 및 제품명 | E39: 062 | F39: 용도 | G39: 119 | H39: 제조연월 및 유통기한 | I39: 171 | J39: 중량용량매수 | K39: 045 | L39: 효과효능 | M39: 042 | N39: 수입자(수입제품에 한함) | O39: 126 | P39: 어린이 보호포장 대상 제품 유무 | Q39: 162 | R39: 제품에 사용된 화학물질 명칭 | S39: 131 | T39: 사용상 주의사항 | U39: 168 | V39: 신고번호(승인번호) | W39: 059 | X39: 소비자상담 관련 전화번호
A40: 038 | B40: 살생물제품 | C40: 047 | D40: 제품명 및 제품유형 | E40: 092 | F40: 중량 또는 용량 및 표준사용량 | G40: 014 | H40: 효과효능 | I40: 161 | J40: 사용대상자 및 사용범위 | K40: 042 | L40: 수입자(수입제품에 한함) | M40: 056 | N40: 어린이보호포장 대상제품 유무 | O40: 083 | P40: 살생물물질, 나노물질, 기타 화학물질(유해화학물질 또는 중점관리물질)의 명칭 | Q40: 050 | R40: 제품 유해성위해성 표시 | S40: 043 | T40: 사용방법 및 사용상 주의사항 | U40: 030 | V40: 승인번호 | W40: 073 | X40: 소비자상담관련 전화번호
...

Sheet 참조_브랜드
A1: ■ 브랜드 정보
A2: 브랜드 번호 | B2: 브랜드 명
A3: 10001 | B3: 뉴트라라이프
A4: 10002 | B4: +XP
A5: 10003 | B5: 1950
A6: 10004 | B6: 1HORA
A7: 10005 | B7: 25년 입학선물 패키지
A8: 10006 | B8: 3D입체퍼즐
A9: 10007 | B9: 3M
A10: 10008 | B10: 808
A11: 10009 | B11: ABH+
A12: 10010 | B12: AGK
A13: 10011 | B13: AGK NORDIC
... A2710: 18000 | B2710: 점프

Sheet 참조_매입처
A1: ■ 매입처 정보
A2: 매입처 번호 | B2: 매입처 명
A3: 44 | B3: [거래종료] 대의산업
A4: 47 | B4: 아리수에듀
A5: 48 | B5: 와우엠지
A6: 50 | B6: ㈜빌트인씨디
A7: 51 | B7: 언어세상
A8: 52 | B8: 제이와이북스(JYBooks)
A9: 53 | B9: 이퍼블릭코리아
A10: 57 | B10: [거래종료] 두레아이들
A11: 58 | B11: [거래종료] 상수리나무
A12: 59 | B12: [거래종료] 현암사
A13: 60 | B13: [거래종료] 다산북스
... A553: 1296 | B553: (주)삼경에프에스

Sheet 참조_제조사
A1: ■ 제조사 정보
A2: 제조사 번호 | B2: 제조사 명
A3: 1202 | B3: 마이피스

Sheet 공통코드수식용
A1: PR002 | B1: PR003 | C1: PR004 | D1: PR006 | E1: PR007 | F1: PR008 | G1: PR010 | H1: PR011 | I1: PR019 | J1: PR023 | K1: PR024 | L1: PR025 | M1: PR026 | N1: PR030 | O1: PR051 | P1: PR060 | Q1: PR061 | R1: PR062 | S1: Y/N | U1: 엑셀버전정보
A2: 10 | B2: 10 | C2: 0 | D2: 10 | E2: 01 | F2: 10 | G2: 01 | H2: 01 | I2: 10 | J2: 10 | K2: 10 | L2: 0 | M2: 01 | N2: 01 | O2: 10 | P2: 10 | Q2: 10 | R2: 10 | S2: Y | U2: V2
A3: 30 | B3: 20 | C3: 15 | D3: 20 | E3: 02 | F3: 20 | G3: 03 | H3: 02 | I3: 11 | J3: 20 | K3: 20 | L3: 1 | M3: 02 | N3: 02 | O3: 20 | P3: 11 | Q3: 11 | R3: 20 | S3: N
C4: 19 | D4: 40 | F4: 30 | G4: 04 | I4: 13 | K4: 30 | L4: 2 | M4: 03 | N4: 03 | O4: 30 | P4: 12 | Q4: 12
I5: 14 | K5: 40 | L5: 3 | M5: 04 | O5: 40 | P5: 13 | Q5: 13
I6: 28 | L6: 4 | M6: 05 | O6: 50 | P6: 14 | Q6: 14
I7: 18 | L7: 5 | M7: 06 | O7: 60 | P7: 15 | Q7: 15
I8: 24 | L8: 6 | M8: 07 | P8: 16 | Q8: 16
I9: 25 | L9: 7 | M9: 08 | P9: 17 | Q9: 17
I10: 26 | L10: 10 | M10: 09 | P10: 18 | Q10: 18
I11: 27 | L11: 14 | M11: 10 | P11: 19 | Q11: 19
I12: 29 | L12: 15 | M12: 11 | Q12: 20
I13: 30 | M13: 12 | Q13: 21
I14: 31 | M14: 13 | Q14: 22
I15: 32 | M15: 14
I16: 33 | M16: 15
I17: 34 | M17: 16
I18: 35 | M18: 17
I19: 98 | M19: 19
I20: 99

Sheet validation check
A1: No. | B1: 오류 유형 | C1: 에러 메시지 호출 조건 | D1: 에러 메시지
A2: 1 | B2: 상품 중복 오류 | C2: DB에 업로드된 상품과 동일한 상품 업로드한 경우 | D2: 이미 존재하는 상품입니다. (상품중복 키 : 상품명, 입점사번호, 표준카테고리 번호, 자체 상품 번호)
A3: 2 | B3: 상품 중복 오류 | C3: 엑셀 파일 내에 4개 키값이 모두 동일한 Row 존재하는 경우 | D3: 엑셀 내에 중복된 상품이 존재합니다. (상품중복 키 : 상품명, 입점사번호, 표준카테고리 번호, 자체 상품 번호)
A4: 3 | B4: 필수값 누락 | C4: 필수입력 항목을 입력하지 않은 경우 | D4: [$컬럼명$] 필수 입력 항목입니다.
B5: 로직 오류 | C5: 상품유형을 'e-쿠폰상품'으로 선택 시, 판매방식을 '예약판매'로 선택한 경우 | D5: [$컬럼명$] 상품유형이 e-쿠폰상품인 경우 일반판매만 입력 가능합니다.
A6: 4 | B6: 필수값 누락 | C6: 판매 방식을 예약 상품으로 선택 시, 필수 컬럼 중 1개 이상 입력하지 않은 경우 (예약주문 가능일시, 예약주문 가능 종료일시, 예약종료후 판매방식, 예약상품 출고지시일) | D6: [$컬럼명$] 예약 상품인 경우 필수 입력 항목입니다.
B7: 로직 오류 | C7: 검색키워드 사용여부를 'Y'로 선택 시, 필수 컬럼을 입력하지 않은 경우(검색키워드) | D7: [$컬럼명$] 검색키워드 사용인 경우 필수 입력 항목입니다.
A8: 5 | B8: 필수값 누락 | C8: 사이즈가이드 사용여부를 ‘사용’으로 선택 시, | D8: [$컬럼명$] 사이즈가이드가 사용인 경우 필수 입력 항목입니다.
C9: 사이즈가이드 등록방법 코드를 입력하지 않은 경우
A10: 6 | B10: 필수값 누락 | C10: 사이즈가이드 등록방법을 기본가이드사용으로 선택 시, | D10: [$컬럼명$] 사이즈가이드 등록방법코드가 기본가이드사용인 경우 필수 입력 항목입니다.
C11: 사이즈가이드 코드를 입력하지 않은 경우
A12: 7 | B12: 필수값 누락 | C12: 사이즈가이드 등록방법을 직접등록으로 선택 시, | D12: [$컬럼명$] 사이즈가이드 등록방법코드가 직접등록인 경우 필수 입력 항목입니다.
C13: 사이즈가이드 내용을 입력하지 않은 경우
A14: 8 | B14: 필수값 누락 | C14: 카테고리 수수료율 적용여부가 N일 시, 공급원가를 입력하지 않은 경우 | D14: [$컬럼명$] 카테고리 수수료율 적용 여부가 N인 경우 필수 입력 항목입니다.
A15: 9 | B15: 필수값 누락 | C15: 거래형태가 위탁판매일 시, 마진율을 입력하지 않은 경우 | D15: [$컬럼명$] 위탁판매의 구간마진인 경우 필수 입력 항목입니다.
B16: 로직 오류 | C16: 상품유형이 '일반상품'인 경우, 배송상품구분은 일반상품, 주문제작만 입력 가능(배송상품구분) | D16: [$컬럼명$] 상품유형이 일반상품인 경우 배송상품구분은 일반상품, 주문제작만 입력 가능합니다.
C17: 상품유형이 'e-쿠폰상품'인 경우, 배송상품구분은 e-쿠폰만 입력 가능(배송상품구분) | D17: [$컬럼명$] 상품유형이 e-쿠폰상품인 경우 배송상품구분은 e-쿠폰만 입력 가능합니다.
B18: 로직 오류 | C18: 배송상품구분이 '일반상품'인 경우, 배송상품구분 상세는 일반상품, 체험상품만 입력 가능(배송상품구분 상세) | D18: [$컬럼명$] 배송상품구분이 일반상품인 경우 배송상품구분 상세는 일반상품, 체험상품만 입력 가능합니다.
C19: 배송상품구분이 '주문제작'인 경우, 배송상품구분 상세는 단체티, 현수막, 글자수당 부과상품만 입력 가능(배송상품구분 상세) | D19: [$컬럼명$] 배송상품구분이 주문제작인 경우 배송상품구분 상세는 단체티, 현수막, 글자수당 부과상품만 입력 가능합니다.
C20: 배송상품구분이 'e-쿠폰'인 경우, 배송상품구분 상세는 사용하지 않음(배송상품구분 상세) | D20: 체크없음
A21: 10 | B21: 필수값 누락 | C21: 구매수량 제한 여부를 ‘제한’으로 선택 시, | D21: [$컬럼명$] 구매수량제한여부가 제한인 경우 필수 입력 항목입니다.
C22: 최소/최대 구매수량을 입력하지 않은 경우
B23: 로직 오류 | C23: 옵션사용여부가 'Y'인 경우, 옵션구분, 옵션분류명, 옵션유형, 옵션값의 입력행 수가 모두 일치해야 함 | D23: 옵션사용 시 옵션구분, 옵션분류명, 옵션유형, 옵션값의 수는 모두 일치해야 합니다.
C24: 미입력 허용
A25: 11 | B25: 필수값 누락 | C25: 표준카테고리의 안전인증대상여부가 ‘대상’ 일 때, | D25: [$컬럼명$] 안전인증대상여부가 인증대상인 경우 필수 입력 항목입니다.
C26: 필수입력 안전인증정보를 입력하지 않은 경우
A27: 12 | B27: 필수값 누락 | C27: 표준카테고리의 안전인증대상여부가 ‘대상’일 때, 안전인증구분n (n≥2) 구성 셀 중 1개 이상 셀을 입력한 후, 이외 값을 모두 입력하지 않은 경우 | D27: [$컬럼명$] 안전인증대상여부가 인증대상이고, 한 개의 안전인증에 하나 이상 셀 값이 입력된 경우 해당 안전인증 셀은 모두 필수 입력 항목입니다.
A28: 13 | B28: 데이터 타입 오류 | C28: 숫자만 입력 가능한 항목에 이외 형태의 데이터 입력 시 (텍스트, 특문 등) | D28: [$컬럼명$] 숫자만 입력해 주세요.
A29: 14 | B29: Byte 길이 오류 | C29: 입력 길이 제한 항목의 Byte를 초과 입력한 경우 | D29: [$컬럼명$] $Byte 제한$ byte 이내로 입력해 주세요.
A30: 15 | B30: 공통코드 입력 오류 | C30: 공통코드 목록 중 선택해야 하는 컬럼에 다른 값을 임의 입력한 경우 | D30: [$컬럼명$] 값은 공통코드 중에서 입력해 주세요.
A31: 16 | B31: 로직 오류 | C31: 엑셀 양식에 다운된 입점사 목록에 없는 입점사를 선택한 경우 | D31: [$컬럼명$] 입점사 목록에 없는 값입니다. 업로드 양식을 최신화하여 입력해 주세요.
A32: 17 | B32: 로직 오류 | C32: 선택한 입점사의 정보와 일치하지 않는 항목을 입력한 경우 (계약정보 등) | D32: [$컬럼명$] 입점사와 일치하지 않는 값입니다. 업로드 양식을 최신화하여 입력해 주세요.
A33: 18 | B33: 로직 오류 | C33: 엑셀 양식에 다운된 표준 카테고리 목록에 없는 표준 카테고리를 선택한 경우 | D33: [$컬럼명$] 리프표준카테고리 목록에 없는 값입니다. 업로드 양식을 최신화하여 입력해 주세요.
A34: 19 | B34: 로직 오류 | C34: 선택한 표준 카테고리의 정보와 일치하지 않는 항목을 입력한 경우 | D34: [$컬럼명$] 리프표준카테고리와 일치하지 않는 값입니다. 업로드 양식을 최신화하여 입력해 주세요.
C35: (상품고시 품목정보 등)
A36: 20 | B36: 로직 오류 | C36: 엑셀 양식에 다운된 브랜드 목록에 없는 브랜드를 선택한 경우 | D36: [$컬럼명$] 브랜드 목록에 없는 값입니다. 업로드 양식을 최신화하여 입력해 주세요.
A37: 21 | B37: 로직 오류 | C37: 선택한 표준 카테고리의 안전인증대상여부가 ‘대상’일 때, | D37: [$컬럼명$] 해당 리프표준카테고리의 안전인증대상여부 값은 인증대상입니다. 업로드 양식을 최신화하여 입력해주세요.
C38: ‘대상 아님’으로 선택한 경우
A39: 22 | B39: 로직 오류 | C39: 등록일 당일 포함 과거 날짜를 입력한 경우 | D39: [$컬럼명$] 오늘 이후 날짜부터 입력 할 수 있습니다.
A40: 23 | B40: 로직 오류 | C40: 종료일시를 시작일시 이전으로 입력한 경우 | D40: [$컬럼명$] 종료일시는 시작일시보다 이후로 입력해 주세요.
...
