Workbook
Name A: #N/A
Name ad: MATCH(광고관리!DayToStart,광고관리!weekdays_reversed,0)-2
Name ad: MATCH(DayToStart,[0]!weekdays_reversed,0)-2
Name AGHAF: MATCH(광고관리!ASFG,광고관리!weekdays_reversed,0)-2
Name AGHAF: MATCH(ASFG,[0]!weekdays_reversed,0)-2
Name ASDFG: #REF!
Name ASDFG: #REF!
Name ASDFGH: MATCH(광고관리!DayToStart,광고관리!weekdays_reversed,0)-2
Name ASDFGH: MATCH(DayToStart,[0]!weekdays_reversed,0)-2
Name ASFG: #REF!
Name ASFG: #REF!
Name d: MATCH(광고관리!sg,광고관리!weekdays_reversed,0)-2
Name d: MATCH(sg,[0]!weekdays_reversed,0)-2
Name DayToStart: #REF!
Name DayToStart: #REF!
Name fds: MATCH(광고관리!DayToStart,광고관리!weekdays_reversed,0)-2
Name fds: MATCH(DayToStart,[0]!weekdays_reversed,0)-2
Name gdfadf: #REF!
Name gdfadf: #REF!
Name HFF: MATCH(광고관리!DayToStart,광고관리!weekdays_reversed,0)-2
Name HFF: MATCH(DayToStart,[0]!weekdays_reversed,0)-2
Name hqsdf: MATCH(광고관리!sg,광고관리!weekdays_reversed,0)-2
Name hqsdf: MATCH(sg,[0]!weekdays_reversed,0)-2
Name MonthToDisplay: #REF!
Name MonthToDisplay: #REF!
Name MonthToDisplayNumber: #N/A
Name S: MATCH(광고관리!DayToStart,광고관리!weekdays_reversed,0)-2
Name S: MATCH(DayToStart,[0]!weekdays_reversed,0)-2
Name sg: #REF!
Name sg: #REF!
Name weekdays_reversed: {"일요일","토요일","금요일","목요일","수요일","화요일","월요일"}
Name weekdays_reversed: {"일요일","토요일","금요일","목요일","수요일","화요일","월요일"}
Name 날짜눈금: 광고관리!요일+광고관리!주*7
Name 날짜눈금: 요일+주*7
Name 날짜패턴: {1,1,2,2,3,3,4,4,5,5,6,6,7}
Name 날짜패턴: {1,1,2,2,3,3,4,4,5,5,6,6,7}
Name 달력: #N/A
Name ㅁ: MATCH(광고관리!DayToStart,광고관리!weekdays_reversed,0)-2
Name ㅁ: MATCH(DayToStart,[0]!weekdays_reversed,0)-2
Name ㅁㄴㅇ: MATCH(광고관리!DayToStart,광고관리!weekdays_reversed,0)-2
Name ㅁㄴㅇ: MATCH(DayToStart,[0]!weekdays_reversed,0)-2
Name ㅁㄴ호ㅗ: MATCH(광고관리!ㅇㄴㅁㄹ,광고관리!weekdays_reversed,0)-2
Name ㅁㄴ호ㅗ: MATCH(ㅇㄴㅁㄹ,[0]!weekdays_reversed,0)-2
Name ㅁㄶ: MATCH(광고관리!ㅇㄴㅁㄹ,광고관리!weekdays_reversed,0)-2
Name ㅁㄶ: MATCH(ㅇㄴㅁㄹ,[0]!weekdays_reversed,0)-2
Name ㅁㅇㄴㅀ: MATCH(광고관리!ㅗㅛㅓㅏㅑㅑ,광고관리!weekdays_reversed,0)-2
Name ㅁㅇㄴㅀ: MATCH(ㅗㅛㅓㅏㅑㅑ,[0]!weekdays_reversed,0)-2
Name ㅁㅎ: MATCH(광고관리!ㅇㄴㅁㄹ,광고관리!weekdays_reversed,0)-2
Name ㅁㅎ: MATCH(ㅇㄴㅁㄹ,[0]!weekdays_reversed,0)-2
Name ㅁㅎㅁㄹ: MATCH(광고관리!DayToStart,광고관리!weekdays_reversed,0)-2
Name ㅁㅎㅁㄹ: MATCH(DayToStart,[0]!weekdays_reversed,0)-2
Name ㅇ2ㅇㄹ: MATCH(광고관리!DayToStart,광고관리!weekdays_reversed,0)-2
Name ㅇ2ㅇㄹ: MATCH(DayToStart,[0]!weekdays_reversed,0)-2
Name ㅇㄴㅁㄹ: #REF!
Name ㅇㄴㅁㄹ: #REF!
Name 요일: {0,1,2,3,4,5,6}
Name 요일: {0,1,2,3,4,5,6}
Name 요일_옵션: MATCH(광고관리!DayToStart,광고관리!weekdays_reversed,0)-2
Name 요일_옵션: MATCH(DayToStart,weekdays_reversed,0)-2
Name 월: {"1월","2월","3월","4월","5월","6월","7월","8월","9월","10월","11월","12월"}

Sheet Dashboard
A1: 쿠팡 로켓 상품 관리 (한눈에 보기)
A2: 기준: 최근월1/2 판매 입력 → 안전재고/발주 자동 산출
A4: 총 상품수 | C4: 판매중 상품수
A5: =COUNTA(상품리스트!$C$2:$C$143) -> 142 | C5: =COUNTIF(상품리스트!#REF!,"판매중") -> #REF!
A7: 재고부족 상품수 | C7: 재고부족 수량(합)
A8: =COUNTIF(상품리스트!$R$2:$R$143,"⚠ 부족") -> 20 | C8: =SUMIF(상품리스트!$R$2:$R$143,"⚠ 부족",상품리스트!$Q$2:$Q$143) -> 25355
A10: 월평균출고(합) | C10: 예상 30일 공급매출(원)
A11: =SUM(상품리스트!$O$2:$O$143) -> 75490 | C11: =SUMPRODUCT(상품리스트!$O$2:$O$143,상품리스트!$D$2:$D$143) -> 81952933
A13: 평균 마진율(판매중) | C13: 재고 커버리지(일)
A14: =AVERAGEIF(상품리스트!#REF!,"판매중",상품리스트!$H$2:$H$143) -> #REF! | C14: =IF(SUM(상품리스트!$O$2:$O$143)=0,"-",SUM(상품리스트!$K$2:$K$143)/(SUM(상품리스트!$O$2:$O$143)/30)) -> 121.9437

Sheet 상품리스트
A1: 상태 | B1: 관리 등급 | C1: 상품명 | D1: 공급가(원) | E1: 원가(원) | F1: 실원가(원) | G1: 마진(원) | H1: 마진율 | I1: 현재고 | J1: 입고예정 | K1: 가용재고 | L1: 1월 | M1: 2월 | N1: 3월 | O1: 월평균출고 | P1: 안전재고 | Q1: 부족수량 | R1: 재고상태 | S1: 재고일수(일) | T1: 발주권장 | U1: 리뷰수 | V1: 별점 | W1: 비고
A2: 판매중 | B2: 핵심 | C2: 50개국세계지도만국기 | D2: 9600 | E2: 7000 | F2: =N(E2)*(1+설정!$B$3) -> 7910 | G2: =N(D2)-F2 -> 1690 | H2: =IF(N(D2)=0,"-",G2/N(D2)) -> 0.17604167 | I2: 2043 | K2: =N(I2)+N(J2) -> 2043 | L2: 1584 | M2: 456 | N2: 360 | O2: =IF(COUNT(L2,M2,N2)=0,0,AVERAGE(L2,M2,N2)) -> 800 | P2: =ROUND(O2*설정!$B$5,0) -> 960 | Q2: =MAX(0,N(P2)-N(K2)) -> 0 | R2: =IF(N(K2)<N(P2),"⚠ 부족","OK") -> OK | S2: =IF(O2=0,"-",K2/(O2/30)) -> 76.6125 | T2: =MAX(0,ROUND(N(P2)*설정!$B$4-N(K2),0)) -> 0 | U2: 2964
A3: 판매중 | B3: 핵심 | C3: 11000찍찍이가방캐치볼(블루) | D3: 4660 | E3: 3100 | F3: =N(E3)*(1+설정!$B$3) -> 3503 | G3: =N(D3)-F3 -> 1157 | H3: =IF(N(D3)=0,"-",G3/N(D3)) -> 0.24828326 | I3: 949 | K3: =N(I3)+N(J3) -> 949 | L3: 264 | M3: 48 | N3: 1272 | O3: =IF(COUNT(L3,M3,N3)=0,0,AVERAGE(L3,M3,N3)) -> 528 | P3: =ROUND(O3*설정!$B$5,0) -> 634 | Q3: =MAX(0,N(P3)-N(K3)) -> 0 | R3: =IF(N(K3)<N(P3),"⚠ 부족","OK") -> OK | S3: =IF(O3=0,"-",K3/(O3/30)) -> 53.920455 | T3: =MAX(0,ROUND(N(P3)*설정!$B$4-N(K3),0)) -> 319 | U3: 665
A4: 판매중 | B4: 핵심 | C4: 1500반짝고슴도치요요(쿠팡용) | D4: 612 | E4: 465 | F4: =N(E4)*(1+설정!$B$3) -> 525.45 | G4: =N(D4)-F4 -> 86.55 | H4: =IF(N(D4)=0,"-",G4/N(D4)) -> 0.14142157 | I4: 12902 | K4: =N(I4)+N(J4) -> 12902 | L4: 9000 | M4: 0 | N4: 8640 | O4: =IF(COUNT(L4,M4,N4)=0,0,AVERAGE(L4,M4,N4)) -> 5880 | P4: =ROUND(O4*설정!$B$5,0) -> 7056 | Q4: =MAX(0,N(P4)-N(K4)) -> 0 | R4: =IF(N(K4)<N(P4),"⚠ 부족","OK") -> OK | S4: =IF(O4=0,"-",K4/(O4/30)) -> 65.826531 | T4: =MAX(0,ROUND(N(P4)*설정!$B$4-N(K4),0)) -> 1210 | U4: 218
A5: 판매중 | B5: 핵심 | C5: 3500아이큐브레인구슬퍼즐(쿠팡용) | D5: 1365 | E5: 1120 | F5: =N(E5)*(1+설정!$B$3) -> 1265.6 | G5: =N(D5)-F5 -> 99.4 | H5: =IF(N(D5)=0,"-",G5/N(D5)) -> 0.072820513 | I5: 4440 | K5: =N(I5)+N(J5) -> 4440 | L5: 6000 | M5: 3840 | N5: 60 | O5: =IF(COUNT(L5,M5,N5)=0,0,AVERAGE(L5,M5,N5)) -> 3300 | P5: =ROUND(O5*설정!$B$5,0) -> 3960 | Q5: =MAX(0,N(P5)-N(K5)) -> 0 | R5: =IF(N(K5)<N(P5),"⚠ 부족","OK") -> OK | S5: =IF(O5=0,"-",K5/(O5/30)) -> 40.363636 | T5: =MAX(0,ROUND(N(P5)*설정!$B$4-N(K5),0)) -> 3480 | U5: 267
A6: 판매중 | B6: 핵심 | C6: 2000바풍투톤슬라임(쿠팡용) | D6: 875 | E6: 550 | F6: =N(E6)*(1+설정!$B$3) -> 621.5 | G6: =N(D6)-F6 -> 253.5 | H6: =IF(N(D6)=0,"-",G6/N(D6)) -> 0.28971429 | I6: 415 | J6: 24000 | K6: =N(I6)+N(J6) -> 24415 | L6: 17280 | M6: 13800 | N6: 240 | O6: =IF(COUNT(L6,M6,N6)=0,0,AVERAGE(L6,M6,N6)) -> 10440 | P6: =ROUND(O6*설정!$B$5,0) -> 12528 | Q6: =MAX(0,N(P6)-N(K6)) -> 0 | R6: =IF(N(K6)<N(P6),"⚠ 부족","OK") -> OK | S6: =IF(O6=0,"-",K6/(O6/30)) -> 70.158046 | T6: =MAX(0,ROUND(N(P6)*설정!$B$4-N(K6),0)) -> 641 | U6: 225
A7: 판매중 | B7: 핵심 | C7: 1000불빛슈팅낙하산(쿠팡용) | D7: 478 | E7: 350 | F7: =N(E7)*(1+설정!$B$3) -> 395.5 | G7: =N(D7)-F7 -> 82.5 | H7: =IF(N(D7)=0,"-",G7/N(D7)) -> 0.17259414 | I7: 14688 | K7: =N(I7)+N(J7) -> 14688 | L7: 972 | M7: 648 | N7: 8424 | O7: =IF(COUNT(L7,M7,N7)=0,0,AVERAGE(L7,M7,N7)) -> 3348 | P7: =ROUND(O7*설정!$B$5,0) -> 4018 | Q7: =MAX(0,N(P7)-N(K7)) -> 0 | R7: =IF(N(K7)<N(P7),"⚠ 부족","OK") -> OK | S7: =IF(O7=0,"-",K7/(O7/30)) -> 131.6129 | T7: =MAX(0,ROUND(N(P7)*설정!$B$4-N(K7),0)) -> 0 | U7: 179
A8: 판매중 | B8: 핵심 | C8: 12색 히어로 사인펜세트5번들(혼합) | D8: 3280 | E8: 2750 | F8: =N(E8)*(1+설정!$B$3) -> 3107.5 | G8: =N(D8)-F8 -> 172.5 | H8: =IF(N(D8)=0,"-",G8/N(D8)) -> 0.052591463 | I8: 2702 | K8: =N(I8)+N(J8) -> 2702 | L8: 2702 | M8: 0 | N8: 224 | O8: =IF(COUNT(L8,M8,N8)=0,0,AVERAGE(L8,M8,N8)) -> 975.33333 | P8: =ROUND(O8*설정!$B$5,0) -> 1170 | Q8: =MAX(0,N(P8)-N(K8)) -> 0 | R8: =IF(N(K8)<N(P8),"⚠ 부족","OK") -> OK | S8: =IF(O8=0,"-",K8/(O8/30)) -> 83.110048 | T8: =MAX(0,ROUND(N(P8)*설정!$B$4-N(K8),0)) -> 0 | U8: 2877
A9: 판매중 | B9: 핵심 | C9: 15000투샷빅파워물총 | D9: 6650 | E9: 3800 | F9: =N(E9)*(1+설정!$B$3) -> 4294 | G9: =N(D9)-F9 -> 2356 | H9: =IF(N(D9)=0,"-",G9/N(D9)) -> 0.35428571 | I9: 179 | K9: =N(I9)+N(J9) -> 179 | O9: =IF(COUNT(L9,M9,N9)=0,0,AVERAGE(L9,M9,N9)) -> 0 | P9: =ROUND(O9*설정!$B$5,0) -> 0 | Q9: =MAX(0,N(P9)-N(K9)) -> 0 | R9: =IF(N(K9)<N(P9),"⚠ 부족","OK") -> OK | S9: =IF(O9=0,"-",K9/(O9/30)) -> - | T9: =MAX(0,ROUND(N(P9)*설정!$B$4-N(K9),0)) -> 0 | U9: 322
A10: 판매중 | B10: 핵심 | C10: 색칠하는에어글라이더 | D10: 1260 | E10: 860 | F10: =N(E10)*(1+설정!$B$3) -> 971.8 | G10: =N(D10)-F10 -> 288.2 | H10: =IF(N(D10)=0,"-",G10/N(D10)) -> 0.22873016 | I10: 1356 | K10: =N(I10)+N(J10) -> 1356 | O10: =IF(COUNT(L10,M10,N10)=0,0,AVERAGE(L10,M10,N10)) -> 0 | P10: =ROUND(O10*설정!$B$5,0) -> 0 | Q10: =MAX(0,N(P10)-N(K10)) -> 0 | R10: =IF(N(K10)<N(P10),"⚠ 부족","OK") -> OK | S10: =IF(O10=0,"-",K10/(O10/30)) -> - | T10: =MAX(0,ROUND(N(P10)*설정!$B$4-N(K10),0)) -> 0 | U10: 46
A11: 판매중 | B11: 핵심 | C11: 3000diy모루인형만들기세트2탄(쿠팡용) | D11: 1072 | E11: 760 | F11: =N(E11)*(1+설정!$B$3) -> 858.8 | G11: =N(D11)-F11 -> 213.2 | H11: =IF(N(D11)=0,"-",G11/N(D11)) -> 0.1988806 | I11: 4133 | K11: =N(I11)+N(J11) -> 4133 | O11: =IF(COUNT(L11,M11,N11)=0,0,AVERAGE(L11,M11,N11)) -> 0 | P11: =ROUND(O11*설정!$B$5,0) -> 0 | Q11: =MAX(0,N(P11)-N(K11)) -> 0 | R11: =IF(N(K11)<N(P11),"⚠ 부족","OK") -> OK | S11: =IF(O11=0,"-",K11/(O11/30)) -> - | T11: =MAX(0,ROUND(N(P11)*설정!$B$4-N(K11),0)) -> 0 | U11: 102
A12: 판매중 | B12: 핵심 | C12: 1500레고블럭 | D12: 487 | E12: 385 | F12: =N(E12)*(1+설정!$B$3) -> 435.05 | G12: =N(D12)-F12 -> 51.95 | H12: =IF(N(D12)=0,"-",G12/N(D12)) -> 0.10667351 | I12: 6582 | K12: =N(I12)+N(J12) -> 6582 | L12: 2664 | M12: 1368 | N12: 2424 | O12: =IF(COUNT(L12,M12,N12)=0,0,AVERAGE(L12,M12,N12)) -> 2152 | P12: =ROUND(O12*설정!$B$5,0) -> 2582 | Q12: =MAX(0,N(P12)-N(K12)) -> 0 | R12: =IF(N(K12)<N(P12),"⚠ 부족","OK") -> OK | S12: =IF(O12=0,"-",K12/(O12/30)) -> 91.756506 | T12: =MAX(0,ROUND(N(P12)*설정!$B$4-N(K12),0)) -> 0 | U12: 81
A13: 판매중 | B13: 핵심 | C13: LCD컬러전자메모보드(8.5인치) | D13: 2096 | E13: 1000 | F13: =N(E13)*(1+설정!$B$3) -> 1130 | G13: =N(D13)-F13 -> 966 | H13: =IF(N(D13)=0,"-",G13/N(D13)) -> 0.46087786 | I13: 724 | K13: =N(I13)+N(J13) -> 724 | L13: 100 | M13: 72 | N13: 172 | O13: =IF(COUNT(L13,M13,N13)=0,0,AVERAGE(L13,M13,N13)) -> 114.66667 | P13: =ROUND(O13*설정!$B$5,0) -> 138 | Q13: =MAX(0,N(P13)-N(K13)) -> 0 | R13: =IF(N(K13)<N(P13),"⚠ 부족","OK") -> OK | S13: =IF(O13=0,"-",K13/(O13/30)) -> 189.4186 | T13: =MAX(0,ROUND(N(P13)*설정!$B$4-N(K13),0)) -> 0 | U13: 59
A14: 판매중 | B14: 핵심 | C14: 11000찍찍이가방캐치볼(핑크) | D14: 4660 | E14: 3100 | F14: =N(E14)*(1+설정!$B$3) -> 3503 | G14: =N(D14)-F14 -> 1157 | H14: =IF(N(D14)=0,"-",G14/N(D14)) -> 0.24828326 | I14: 685 | K14: =N(I14)+N(J14) -> 685 | N14: 288 | O14: =IF(COUNT(L14,M14,N14)=0,0,AVERAGE(L14,M14,N14)) -> 288 | P14: =ROUND(O14*설정!$B$5,0) -> 346 | Q14: =MAX(0,N(P14)-N(K14)) -> 0 | R14: =IF(N(K14)<N(P14),"⚠ 부족","OK") -> OK | S14: =IF(O14=0,"-",K14/(O14/30)) -> 71.354167 | T14: =MAX(0,ROUND(N(P14)*설정!$B$4-N(K14),0)) -> 7 | U14: 615
A15: 판매중 | B15: 핵심 | C15: 3000잔디인형키우기(곰돌이) | D15: 1102 | E15: 895 | F15: =N(E15)*(1+설정!$B$3) -> 1011.35 | G15: =N(D15)-F15 -> 90.65 | H15: =IF(N(D15)=0,"-",G15/N(D15)) -> 0.082259528 | I15: 3076 | K15: =N(I15)+N(J15) -> 3076 | L15: 3360 | M15: 3600 | O15: =IF(COUNT(L15,M15,N15)=0,0,AVERAGE(L15,M15,N15)) -> 3480 | P15: =ROUND(O15*설정!$B$5,0) -> 4176 | Q15: =MAX(0,N(P15)-N(K15)) -> 1100 | R15: =IF(N(K15)<N(P15),"⚠ 부족","OK") -> ⚠ 부족 | S15: =IF(O15=0,"-",K15/(O15/30)) -> 26.517241 | T15: =MAX(0,ROUND(N(P15)*설정!$B$4-N(K15),0)) -> 5276 | U15: 100
A16: 판매중 | B16: 핵심 | C16: 파도(S형)LED발목줄넘기(쿠팡용) | D16: 2925 | E16: 1760 | F16: =N(E16)*(1+설정!$B$3) -> 1988.8 | G16: =N(D16)-F16 -> 936.2 | H16: =IF(N(D16)=0,"-",G16/N(D16)) -> 0.32006838 | I16: 348 | K16: =N(I16)+N(J16) -> 348 | L16: 122 | M16: 220 | N16: 102 | O16: =IF(COUNT(L16,M16,N16)=0,0,AVERAGE(L16,M16,N16)) -> 148 | P16: =ROUND(O16*설정!$B$5,0) -> 178 | Q16: =MAX(0,N(P16)-N(K16)) -> 0 | R16: =IF(N(K16)<N(P16),"⚠ 부족","OK") -> OK | S16: =IF(O16=0,"-",K16/(O16/30)) -> 70.540541 | T16: =MAX(0,ROUND(N(P16)*설정!$B$4-N(K16),0)) -> 8 | U16: 78
A17: 판매중 | B17: 핵심 | C17: 1000제로탄산슬라임 | D17: 379 | E17: 340 | F17: =N(E17)*(1+설정!$B$3) -> 384.2 | G17: =N(D17)-F17 -> -5.2 | H17: =IF(N(D17)=0,"-",G17/N(D17)) -> -0.013720317 | I17: -64 | J17: 21600 | K17: =N(I17)+N(J17) -> 21536 | O17: =IF(COUNT(L17,M17,N17)=0,0,AVERAGE(L17,M17,N17)) -> 0 | P17: =ROUND(O17*설정!$B$5,0) -> 0 | Q17: =MAX(0,N(P17)-N(K17)) -> 0 | R17: =IF(N(K17)<N(P17),"⚠ 부족","OK") -> OK | S17: =IF(O17=0,"-",K17/(O17/30)) -> - | T17: =MAX(0,ROUND(N(P17)*설정!$B$4-N(K17),0)) -> 0 | U17: 191
A18: 판매중 | B18: 핵심 | C18: 3000글라이더 | D18: 921 | E18: 650 | F18: =N(E18)*(1+설정!$B$3) -> 734.5 | G18: =N(D18)-F18 -> 186.5 | H18: =IF(N(D18)=0,"-",G18/N(D18)) -> 0.20249729 | I18: 121 | K18: =N(I18)+N(J18) -> 121 | M18: 132 | N18: 1992 | O18: =IF(COUNT(L18,M18,N18)=0,0,AVERAGE(L18,M18,N18)) -> 1062 | P18: =ROUND(O18*설정!$B$5,0) -> 1274 | Q18: =MAX(0,N(P18)-N(K18)) -> 1153 | R18: =IF(N(K18)<N(P18),"⚠ 부족","OK") -> ⚠ 부족 | S18: =IF(O18=0,"-",K18/(O18/30)) -> 3.4180791 | T18: =MAX(0,ROUND(N(P18)*설정!$B$4-N(K18),0)) -> 2427 | U18: 127
A19: 판매중 | B19: 핵심 | C19: 2500롱스틱물총(유니콘) | D19: 898 | E19: 726 | F19: =N(E19)*(1+설정!$B$3) -> 820.38 | G19: =N(D19)-F19 -> 77.62 | H19: =IF(N(D19)=0,"-",G19/N(D19)) -> 0.086436526 | I19: 3 | K19: =N(I19)+N(J19) -> 3 | N19: 7854 | O19: =IF(COUNT(L19,M19,N19)=0,0,AVERAGE(L19,M19,N19)) -> 7854 | P19: =ROUND(O19*설정!$B$5,0) -> 9425 | Q19: =MAX(0,N(P19)-N(K19)) -> 9422 | R19: =IF(N(K19)<N(P19),"⚠ 부족","OK") -> ⚠ 부족 | S19: =IF(O19=0,"-",K19/(O19/30)) -> 0.011459129 | T19: =MAX(0,ROUND(N(P19)*설정!$B$4-N(K19),0)) -> 18847 | U19: 144
A20: 판매중 | B20: 핵심 | C20: 1500샤이니무지개칼라링 | D20: 390 | E20: 320 | F20: =N(E20)*(1+설정!$B$3) -> 361.6 | G20: =N(D20)-F20 -> 28.4 | H20: =IF(N(D20)=0,"-",G20/N(D20)) -> 0.072820513 | I20: 9107 | K20: =N(I20)+N(J20) -> 9107 | L20: 792 | M20: 3000 | N20: 1344 | O20: =IF(COUNT(L20,M20,N20)=0,0,AVERAGE(L20,M20,N20)) -> 1712 | P20: =ROUND(O20*설정!$B$5,0) -> 2054 | Q20: =MAX(0,N(P20)-N(K20)) -> 0 | R20: =IF(N(K20)<N(P20),"⚠ 부족","OK") -> OK | S20: =IF(O20=0,"-",K20/(O20/30)) -> 159.58528 | T20: =MAX(0,ROUND(N(P20)*설정!$B$4-N(K20),0)) -> 0 | U20: 556
A21: 판매중 | B21: 핵심 | C21: 해피원목칠교(중) | D21: 1473 | E21: 1150 | F21: =N(E21)*(1+설정!$B$3) -> 1299.5 | G21: =N(D21)-F21 -> 173.5 | H21: =IF(N(D21)=0,"-",G21/N(D21)) -> 0.11778683 | I21: 1663 | K21: =N(I21)+N(J21) -> 1663 | M21: 144 | N21: 88 | O21: =IF(COUNT(L21,M21,N21)=0,0,AVERAGE(L21,M21,N21)) -> 116 | P21: =ROUND(O21*설정!$B$5,0) -> 139 | Q21: =MAX(0,N(P21)-N(K21)) -> 0 | R21: =IF(N(K21)<N(P21),"⚠ 부족","OK") -> OK | S21: =IF(O21=0,"-",K21/(O21/30)) -> 430.08621 | T21: =MAX(0,ROUND(N(P21)*설정!$B$4-N(K21),0)) -> 0 | U21: 116
A22: 판매중 | B22: 핵심 | C22: 1000고리걸기수중게임(쿠팡용) | D22: 410 | E22: 300 | F22: =N(E22)*(1+설정!$B$3) -> 339 | G22: =N(D22)-F22 -> 71 | H22: =IF(N(D22)=0,"-",G22/N(D22)) -> 0.17317073 | I22: 32 | K22: =N(I22)+N(J22) -> 32 | L22: 1840 | M22: 3200 | N22: 2560 | O22: =IF(COUNT(L22,M22,N22)=0,0,AVERAGE(L22,M22,N22)) -> 2533.3333 | P22: =ROUND(O22*설정!$B$5,0) -> 3040 | Q22: =MAX(0,N(P22)-N(K22)) -> 3008 | R22: =IF(N(K22)<N(P22),"⚠ 부족","OK") -> ⚠ 부족 | S22: =IF(O22=0,"-",K22/(O22/30)) -> 0.37894737 | T22: =MAX(0,ROUND(N(P22)*설정!$B$4-N(K22),0)) -> 6048 | U22: 138
A23: 판매중 | B23: 육성 | C23: 2500LED탱탱바운스손목공 | D23: 946 | E23: 760 | F23: =N(E23)*(1+설정!$B$3) -> 858.8 | G23: =N(D23)-F23 -> 87.2 | H23: =IF(N(D23)=0,"-",G23/N(D23)) -> 0.09217759 | I23: 917 | K23: =N(I23)+N(J23) -> 917 | L23: 372 | M23: 1008 | N23: 408 | O23: =IF(COUNT(L23,M23,N23)=0,0,AVERAGE(L23,M23,N23)) -> 596 | P23: =ROUND(O23*설정!$B$5,0) -> 715 | Q23: =MAX(0,N(P23)-N(K23)) -> 0 | R23: =IF(N(K23)<N(P23),"⚠ 부족","OK") -> OK | S23: =IF(O23=0,"-",K23/(O23/30)) -> 46.157718 | T23: =MAX(0,ROUND(N(P23)*설정!$B$4-N(K23),0)) -> 513 | U23: 26
A24: 판매중 | B24: 육성 | C24: 2000퓨어클리어슬라임 | D24: 959 | E24: 550 | F24: =N(E24)*(1+설정!$B$3) -> 621.5 | G24: =N(D24)-F24 -> 337.5 | H24: =IF(N(D24)=0,"-",G24/N(D24)) -> 0.35192909 | I24: 5129 | K24: =N(I24)+N(J24) -> 5129 | L24: 1092 | M24: 2187 | N24: 879 | O24: =IF(COUNT(L24,M24,N24)=0,0,AVERAGE(L24,M24,N24)) -> 1386 | P24: =ROUND(O24*설정!$B$5,0) -> 1663 | Q24: =MAX(0,N(P24)-N(K24)) -> 0 | R24: =IF(N(K24)<N(P24),"⚠ 부족","OK") -> OK | S24: =IF(O24=0,"-",K24/(O24/30)) -> 111.01732 | T24: =MAX(0,ROUND(N(P24)*설정!$B$4-N(K24),0)) -> 0 | U24: 41
A25: 판매중 | B25: 육성 | C25: 2500유니콘워터게임기 | D25: 893 | E25: 745 | F25: =N(E25)*(1+설정!$B$3) -> 841.85 | G25: =N(D25)-F25 -> 51.15 | H25: =IF(N(D25)=0,"-",G25/N(D25)) -> 0.057278835 | I25: 1 | J25: 5760 | K25: =N(I25)+N(J25) -> 5761 | L25: 1640 | O25: =IF(COUNT(L25,M25,N25)=0,0,AVERAGE(L25,M25,N25)) -> 1640 | P25: =ROUND(O25*설정!$B$5,0) -> 1968 | Q25: =MAX(0,N(P25)-N(K25)) -> 0 | R25: =IF(N(K25)<N(P25),"⚠ 부족","OK") -> OK | S25: =IF(O25=0,"-",K25/(O25/30)) -> 105.38415 | T25: =MAX(0,ROUND(N(P25)*설정!$B$4-N(K25),0)) -> 0 | U25: 120
A26: 판매중 | B26: 육성 | C26: 8000해피원목테트리스퍼즐 | D26: 3043 | E26: 2300 | F26: =N(E26)*(1+설정!$B$3) -> 2599 | G26: =N(D26)-F26 -> 444 | H26: =IF(N(D26)=0,"-",G26/N(D26)) -> 0.14590864 | I26: 907 | K26: =N(I26)+N(J26) -> 907 | L26: 328 | M26: 432 | N26: 208 | O26: =IF(COUNT(L26,M26,N26)=0,0,AVERAGE(L26,M26,N26)) -> 322.66667 | P26: =ROUND(O26*설정!$B$5,0) -> 387 | Q26: =MAX(0,N(P26)-N(K26)) -> 0 | R26: =IF(N(K26)<N(P26),"⚠ 부족","OK") -> OK | S26: =IF(O26=0,"-",K26/(O26/30)) -> 84.328512 | T26: =MAX(0,ROUND(N(P26)*설정!$B$4-N(K26),0)) -> 0 | U26: 85
A27: 판매중 | B27: 육성 | C27: 4500전통낚시대연날리기(쿠팡용) | D27: 2058 | E27: 1285 | F27: =N(E27)*(1+설정!$B$3) -> 1452.05 | G27: =N(D27)-F27 -> 605.95 | H27: =IF(N(D27)=0,"-",G27/N(D27)) -> 0.29443635 | I27: 152 | K27: =N(I27)+N(J27) -> 152 | L27: 408 | N27: 1284 | O27: =IF(COUNT(L27,M27,N27)=0,0,AVERAGE(L27,M27,N27)) -> 846 | P27: =ROUND(O27*설정!$B$5,0) -> 1015 | Q27: =MAX(0,N(P27)-N(K27)) -> 863 | R27: =IF(N(K27)<N(P27),"⚠ 부족","OK") -> ⚠ 부족 | S27: =IF(O27=0,"-",K27/(O27/30)) -> 5.3900709 | T27: =MAX(0,ROUND(N(P27)*설정!$B$4-N(K27),0)) -> 1878 | U27: 37
A28: 판매중 | B28: 육성 | C28: 8000종치기퍼즐게임(쿠팡용) | D28: 2975 | E28: 2400 | F28: =N(E28)*(1+설정!$B$3) -> 2712 | G28: =N(D28)-F28 -> 263 | H28: =IF(N(D28)=0,"-",G28/N(D28)) -> 0.088403361 | I28: 2548 | K28: =N(I28)+N(J28) -> 2548 | L28: 2568 | M28: 1704 | N28: 1528 | O28: =IF(COUNT(L28,M28,N28)=0,0,AVERAGE(L28,M28,N28)) -> 1933.3333 | P28: =ROUND(O28*설정!$B$5,0) -> 2320 | Q28: =MAX(0,N(P28)-N(K28)) -> 0 | R28: =IF(N(K28)<N(P28),"⚠ 부족","OK") -> OK | S28: =IF(O28=0,"-",K28/(O28/30)) -> 39.537931 | T28: =MAX(0,ROUND(N(P28)*설정!$B$4-N(K28),0)) -> 2092 | U28: 46
A29: 판매중 | B29: 육성 | C29: 2500해피불빛캐치볼(쿠팡용) | D29: 1200 | E29: 935 | F29: =N(E29)*(1+설정!$B$3) -> 1056.55 | G29: =N(D29)-F29 -> 143.45 | H29: =IF(N(D29)=0,"-",G29/N(D29)) -> 0.11954167 | I29: 2006 | K29: =N(I29)+N(J29) -> 2006 | L29: 2946 | M29: 944 | N29: 2616 | O29: =IF(COUNT(L29,M29,N29)=0,0,AVERAGE(L29,M29,N29)) -> 2168.6667 | P29: =ROUND(O29*설정!$B$5,0) -> 2602 | Q29: =MAX(0,N(P29)-N(K29)) -> 596 | R29: =IF(N(K29)<N(P29),"⚠ 부족","OK") -> ⚠ 부족 | S29: =IF(O29=0,"-",K29/(O29/30)) -> 27.749769 | T29: =MAX(0,ROUND(N(P29)*설정!$B$4-N(K29),0)) -> 3198 | U29: 82
A30: 판매중 | B30: 육성 | C30: 2500롱스틱물총(아기상어) | D30: 864 | E30: 726 | F30: =N(E30)*(1+설정!$B$3) -> 820.38 | G30: =N(D30)-F30 -> 43.62 | H30: =IF(N(D30)=0,"-",G30/N(D30)) -> 0.050486111 | I30: 108 | K30: =N(I30)+N(J30) -> 108 | L30: 6 | M30: 12 | N30: 234 | O30: =IF(COUNT(L30,M30,N30)=0,0,AVERAGE(L30,M30,N30)) -> 84 | P30: =ROUND(O30*설정!$B$5,0) -> 101 | Q30: =MAX(0,N(P30)-N(K30)) -> 0 | R30: =IF(N(K30)<N(P30),"⚠ 부족","OK") -> OK | S30: =IF(O30=0,"-",K30/(O30/30)) -> 38.571429 | T30: =MAX(0,ROUND(N(P30)*설정!$B$4-N(K30),0)) -> 94
A31: 판매중 | B31: 육성 | C31: 해피원목칠교(소) | D31: 744 | E31: 560 | F31: =N(E31)*(1+설정!$B$3) -> 632.8 | G31: =N(D31)-F31 -> 111.2 | H31: =IF(N(D31)=0,"-",G31/N(D31)) -> 0.14946237 | I31: 279 | K31: =N(I31)+N(J31) -> 279 | L31: 256 | M31: 1440 | N31: 192 | O31: =IF(COUNT(L31,M31,N31)=0,0,AVERAGE(L31,M31,N31)) -> 629.33333 | P31: =ROUND(O31*설정!$B$5,0) -> 755 | Q31: =MAX(0,N(P31)-N(K31)) -> 476 | R31: =IF(N(K31)<N(P31),"⚠ 부족","OK") -> ⚠ 부족 | S31: =IF(O31=0,"-",K31/(O31/30)) -> 13.299788 | T31: =MAX(0,ROUND(N(P31)*설정!$B$4-N(K31),0)) -> 1231 | U31: 19
A32: 판매중 | B32: 육성 | C32: 4000LED반짝윙윙바람개비버블세트 | D32: 1398 | E32: 1200 | F32: =N(E32)*(1+설정!$B$3) -> 1356 | G32: =N(D32)-F32 -> 42 | H32: =IF(N(D32)=0,"-",G32/N(D32)) -> 0.030042918 | I32: 4 | K32: =N(I32)+N(J32) -> 4 | M32: 40 | O32: =IF(COUNT(L32,M32,N32)=0,0,AVERAGE(L32,M32,N32)) -> 40 | P32: =ROUND(O32*설정!$B$5,0) -> 48 | Q32: =MAX(0,N(P32)-N(K32)) -> 44 | R32: =IF(N(K32)<N(P32),"⚠ 부족","OK") -> ⚠ 부족 | S32: =IF(O32=0,"-",K32/(O32/30)) -> 3 | T32: =MAX(0,ROUND(N(P32)*설정!$B$4-N(K32),0)) -> 92 | U32: 34
A33: 판매중 | B33: 육성 | C33: 3000잔디인형키우기(못난이) | D33: 1102 | E33: 895 | F33: =N(E33)*(1+설정!$B$3) -> 1011.35 | G33: =N(D33)-F33 -> 90.65 | H33: =IF(N(D33)=0,"-",G33/N(D33)) -> 0.082259528 | I33: 949 | K33: =N(I33)+N(J33) -> 949 | L33: 1164 | N33: 480 | O33: =IF(COUNT(L33,M33,N33)=0,0,AVERAGE(L33,M33,N33)) -> 822 | P33: =ROUND(O33*설정!$B$5,0) -> 986 | Q33: =MAX(0,N(P33)-N(K33)) -> 37 | R33: =IF(N(K33)<N(P33),"⚠ 부족","OK") -> ⚠ 부족 | S33: =IF(O33=0,"-",K33/(O33/30)) -> 34.635036 | T33: =MAX(0,ROUND(N(P33)*설정!$B$4-N(K33),0)) -> 1023 | U33: 43
A34: 판매중 | B34: 육성 | C34: 1200러브오리비눗방울 | D34: 406 | E34: 260 | F34: =N(E34)*(1+설정!$B$3) -> 293.8 | G34: =N(D34)-F34 -> 112.2 | H34: =IF(N(D34)=0,"-",G34/N(D34)) -> 0.27635468 | I34: 0 | K34: =N(I34)+N(J34) -> 0 | O34: =IF(COUNT(L34,M34,N34)=0,0,AVERAGE(L34,M34,N34)) -> 0 | P34: =ROUND(O34*설정!$B$5,0) -> 0 | Q34: =MAX(0,N(P34)-N(K34)) -> 0 | R34: =IF(N(K34)<N(P34),"⚠ 부족","OK") -> OK | S34: =IF(O34=0,"-",K34/(O34/30)) -> - | T34: =MAX(0,ROUND(N(P34)*설정!$B$4-N(K34),0)) -> 0 | U34: 11
A35: 판매중 | B35: 육성 | C35: 꼬꼬반자동연필깎이 | D35: 2922 | E35: 1900 | F35: =N(E35)*(1+설정!$B$3) -> 2147 | G35: =N(D35)-F35 -> 775 | H35: =IF(N(D35)=0,"-",G35/N(D35)) -> 0.2652293 | I35: 404 | K35: =N(I35)+N(J35) -> 404 | L35: 46 | M35: 42 | O35: =IF(COUNT(L35,M35,N35)=0,0,AVERAGE(L35,M35,N35)) -> 44 | P35: =ROUND(O35*설정!$B$5,0) -> 53 | Q35: =MAX(0,N(P35)-N(K35)) -> 0 | R35: =IF(N(K35)<N(P35),"⚠ 부족","OK") -> OK | S35: =IF(O35=0,"-",K35/(O35/30)) -> 275.45455 | T35: =MAX(0,ROUND(N(P35)*설정!$B$4-N(K35),0)) -> 0
A36: 판매중 | B36: 육성 | C36: 15000(250배)정밀현미경관찰세트 | D36: 6825 | E36: 3900 | F36: =N(E36)*(1+설정!$B$3) -> 4407 | G36: =N(D36)-F36 -> 2418 | H36: =IF(N(D36)=0,"-",G36/N(D36)) -> 0.35428571 | I36: 11 | K36: =N(I36)+N(J36) -> 11 | L36: 243 | M36: 206 | N36: 2 | O36: =IF(COUNT(L36,M36,N36)=0,0,AVERAGE(L36,M36,N36)) -> 224.5 | P36: =ROUND(O36*설정!$B$5,0) -> 269 | Q36: =MAX(0,N(P36)-N(K36)) -> 258 | R36: =IF(N(K36)<N(P36),"⚠ 부족","OK") -> ⚠ 부족 | S36: =IF(O36=0,"-",K36/(O36/30)) -> 1.4699332 | T36: =MAX(0,ROUND(N(P36)*설정!$B$4-N(K36),0)) -> 527
A37: 판매중 | B37: 육성 | C37: 8000멀티라켓볼세트 | D37: 4826 | E37: 2200 | F37: =N(E37)*(1+설정!$B$3) -> 2486 | G37: =N(D37)-F37 -> 2340 | H37: =IF(N(D37)=0,"-",G37/N(D37)) -> 0.4848736 | I37: 47 | K37: =N(I37)+N(J37) -> 47 | N37: 3 | O37: =IF(COUNT(L37,M37,N37)=0,0,AVERAGE(L37,M37,N37)) -> 3 | P37: =ROUND(O37*설정!$B$5,0) -> 4 | Q37: =MAX(0,N(P37)-N(K37)) -> 0 | R37: =IF(N(K37)<N(P37),"⚠ 부족","OK") -> OK | S37: =IF(O37=0,"-",K37/(O37/30)) -> 470 | T37: =MAX(0,ROUND(N(P37)*설정!$B$4-N(K37),0)) -> 0
A38: 판매중 | B38: 육성 | C38: 3500LED글라이더 | D38: 1238 | E38: 830 | F38: =N(E38)*(1+설정!$B$3) -> 937.9 | G38: =N(D38)-F38 -> 300.1 | H38: =IF(N(D38)=0,"-",G38/N(D38)) -> 0.24240711 | I38: 532 | K38: =N(I38)+N(J38) -> 532 | O38: =IF(COUNT(L38,M38,N38)=0,0,AVERAGE(L38,M38,N38)) -> 0 | P38: =ROUND(O38*설정!$B$5,0) -> 0 | Q38: =MAX(0,N(P38)-N(K38)) -> 0 | R38: =IF(N(K38)<N(P38),"⚠ 부족","OK") -> OK | S38: =IF(O38=0,"-",K38/(O38/30)) -> - | T38: =MAX(0,ROUND(N(P38)*설정!$B$4-N(K38),0)) -> 0
A39: 판매중 | B39: 육성 | C39: 3000길어져랏안테나잠자리채 | D39: 1328 | E39: 970 | F39: =N(E39)*(1+설정!$B$3) -> 1096.1 | G39: =N(D39)-F39 -> 231.9 | H39: =IF(N(D39)=0,"-",G39/N(D39)) -> 0.17462349 | I39: 0 | J39: 4800 | K39: =N(I39)+N(J39) -> 4800 | M39: 21 | O39: =IF(COUNT(L39,M39,N39)=0,0,AVERAGE(L39,M39,N39)) -> 21 | P39: =ROUND(O39*설정!$B$5,0) -> 25 | Q39: =MAX(0,N(P39)-N(K39)) -> 0 | R39: =IF(N(K39)<N(P39),"⚠ 부족","OK") -> OK | S39: =IF(O39=0,"-",K39/(O39/30)) -> 6857.1429 | T39: =MAX(0,ROUND(N(P39)*설정!$B$4-N(K39),0)) -> 0
A40: 판매중 | B40: 육성 | C40: 해피원목칠교(대) | D40: 2340 | E40: 1800 | F40: =N(E40)*(1+설정!$B$3) -> 2034 | G40: =N(D40)-F40 -> 306 | H40: =IF(N(D40)=0,"-",G40/N(D40)) -> 0.13076923 | I40: 1400 | K40: =N(I40)+N(J40) -> 1400 | O40: =IF(COUNT(L40,M40,N40)=0,0,AVERAGE(L40,M40,N40)) -> 0 | P40: =ROUND(O40*설정!$B$5,0) -> 0 | Q40: =MAX(0,N(P40)-N(K40)) -> 0 | R40: =IF(N(K40)<N(P40),"⚠ 부족","OK") -> OK | S40: =IF(O40=0,"-",K40/(O40/30)) -> - | T40: =MAX(0,ROUND(N(P40)*설정!$B$4-N(K40),0)) -> 0
...

Sheet 광고관리
A1: 연간목표
A2: 매출목표 | B2: 1500000000 | C2: 월 매출 목표 (평균) | D2: =B2/12 -> 125000000
A3: 광고비율 (매출 대비) | B3: 0.02 | C3: 월 광고예산 (평균) | D3: =D2*B3 -> 2500000
A4: 평균 판매가 | B4: 10000 | C4: 일 광고예산 (평균) | D4: =D3/30 -> 83333.333
A5: 예상 전환율(CVR) | B5: 0.07
A6: 평균 CPC(원) | B6: 120 | C6: 150원~300원
A7: 목표 ROAS | B7: 6 | C7: 500~700% 안정 (광고 매출 ÷ 광고비) × 100
A10: 쿠팡로켓 월별 광고 성과 관리
A12: 월 | B12: 25년매출 | C12: 목표매출 | D12: 실매출 | E12: 광고예산(원) | F12: 실제광고비 | G12: 노출 | H12: 클릭 | I12: 주문 | J12: 광고매출 | K12: ROAS 500~700% 이상 | L12: ACOS 10~15% 이하 | M12: CPC(원) 150~300원 | N12: 전환율(CVR) 5~7%이상 | O12: 클릭율 (CTR) 0.7% 이상
A13: 1월 | B13: 35908513 | C13: 40000000 | D13: 97278033 | E13: 1500000 | F13: 1397548 | G13: 7588181 | H13: 12402 | I13: 990 | J13: 13947340 | K13: =IFERROR(J13/F13,0) -> 9.9798647 | L13: =IFERROR(F13/J13,0) -> 0.10020176 | M13: =IFERROR(F13/H13,0) -> 112.68731 | N13: =IFERROR(I13/H13,0) -> 0.079825835 | O13: =IFERROR(H13/G13,0) -> 0.0016343838
A14: 2월 | B14: 36279505 | C14: 50000000 | D14: 63568333 | E14: 1500000 | F14: 1400544 | G14: 5571104 | H14: 10771 | I14: 785 | J14: 11622740 | K14: =IFERROR(J14/F14,0) -> 8.2987325 | L14: =IFERROR(F14/J14,0) -> 0.12050033 | M14: =IFERROR(F14/H14,0) -> 130.02915 | N14: =IFERROR(I14/H14,0) -> 0.072880884 | O14: =IFERROR(H14/G14,0) -> 0.001933369
A15: 3월 | B15: 81087922 | C15: 80000000 | D15: 38165274 | E15: 2000000 | F15: 1123178 | G15: 0 | H15: 0 | I15: 0 | J15: 0 | K15: =IFERROR(J15/F15,0) -> 0 | L15: =IFERROR(F15/J15,0) -> 0 | M15: =IFERROR(F15/H15,0) -> 0 | N15: =IFERROR(I15/H15,0) -> 0 | O15: =IFERROR(H15/G15,0) -> 0
A16: 4월 | B16: 97897947 | C16: 100000000 | D16: 0 | E16: 2000000 | F16: 0 | G16: 0 | H16: 0 | I16: 0 | J16: 0 | K16: =IFERROR(J16/F16,0) -> 0 | L16: =IFERROR(F16/J16,0) -> 0 | M16: =IFERROR(F16/H16,0) -> 0 | N16: =IFERROR(I16/H16,0) -> 0 | O16: =IFERROR(H16/G16,0) -> 0
A17: 5월 | B17: 113966483 | C17: 140000000 | D17: 0 | E17: 2500000 | F17: 0 | G17: 0 | H17: 0 | I17: 0 | J17: 0 | K17: =IFERROR(J17/F17,0) -> 0 | L17: =IFERROR(F17/J17,0) -> 0 | M17: =IFERROR(F17/H17,0) -> 0 | N17: =IFERROR(I17/H17,0) -> 0 | O17: =IFERROR(H17/G17,0) -> 0
A18: 6월 | B18: 92876437 | C18: 150000000 | D18: 0 | E18: 2000000 | F18: 0 | G18: 0 | H18: 0 | I18: 0 | J18: 0 | K18: =IFERROR(J18/F18,0) -> 0 | L18: =IFERROR(F18/J18,0) -> 0 | M18: =IFERROR(F18/H18,0) -> 0 | N18: =IFERROR(I18/H18,0) -> 0 | O18: =IFERROR(H18/G18,0) -> 0
A19: 7월 | B19: 141712487 | C19: 170000000 | D19: 0 | E19: 2500000 | F19: 0 | G19: 0 | H19: 0 | I19: 0 | J19: 0 | K19: =IFERROR(J19/F19,0) -> 0 | L19: =IFERROR(F19/J19,0) -> 0 | M19: =IFERROR(F19/H19,0) -> 0 | N19: =IFERROR(I19/H19,0) -> 0 | O19: =IFERROR(H19/G19,0) -> 0
A20: 8월 | B20: 56194903 | C20: 150000000 | D20: 0 | E20: 2000000 | F20: 0 | G20: 0 | H20: 0 | I20: 0 | J20: 0 | K20: =IFERROR(J20/F20,0) -> 0 | L20: =IFERROR(F20/J20,0) -> 0 | M20: =IFERROR(F20/H20,0) -> 0 | N20: =IFERROR(I20/H20,0) -> 0 | O20: =IFERROR(H20/G20,0) -> 0
A21: 9월 | B21: 91298500 | C21: 160000000 | D21: 0 | E21: 2500000 | F21: 0 | G21: 0 | H21: 0 | I21: 0 | J21: 0 | K21: =IFERROR(J21/F21,0) -> 0 | L21: =IFERROR(F21/J21,0) -> 0 | M21: =IFERROR(F21/H21,0) -> 0 | N21: =IFERROR(I21/H21,0) -> 0 | O21: =IFERROR(H21/G21,0) -> 0
A22: 10월 | B22: 89560705 | C22: 160000000 | D22: 0 | E22: 2500000 | F22: 0 | G22: 0 | H22: 0 | I22: 0 | J22: 0 | K22: =IFERROR(J22/F22,0) -> 0 | L22: =IFERROR(F22/J22,0) -> 0 | M22: =IFERROR(F22/H22,0) -> 0 | N22: =IFERROR(I22/H22,0) -> 0 | O22: =IFERROR(H22/G22,0) -> 0
A23: 11월 | B23: 87410343 | C23: 150000000 | D23: 0 | E23: 2000000 | F23: 0 | G23: 0 | H23: 0 | I23: 0 | J23: 0 | K23: =IFERROR(J23/F23,0) -> 0 | L23: =IFERROR(F23/J23,0) -> 0 | M23: =IFERROR(F23/H23,0) -> 0 | N23: =IFERROR(I23/H23,0) -> 0 | O23: =IFERROR(H23/G23,0) -> 0
A24: 12월 | B24: 50951052 | C24: 150000000 | D24: 0 | E24: 2000000 | F24: 0 | G24: 0 | H24: 0 | I24: 0 | J24: 0 | K24: =IFERROR(J24/F24,0) -> 0 | L24: =IFERROR(F24/J24,0) -> 0 | M24: =IFERROR(F24/H24,0) -> 0 | N24: =IFERROR(I24/H24,0) -> 0 | O24: =IFERROR(H24/G24,0) -> 0
A25: 합계 | B25: =SUM(B13:B24) -> 975144797 | C25: =SUM(C13:C24) -> 1500000000 | D25: =SUM(D13:D24) -> 199011640 | E25: =SUM(E13:E24) -> 25000000 | F25: =SUM(F13:F24) -> 3921270 | G25: =SUM(G13:G24) -> 13159285 | H25: =SUM(H13:H24) -> 23173 | I25: =SUM(I13:I24) -> 1775 | J25: =SUM(J13:J24) -> 25570080 | K25: =IFERROR(J25/F25,0) -> 6.520867 | L25: =IFERROR(F25/J25,0) -> 0.15335384 | M25: =IFERROR(F25/H25,0) -> 169.21719 | N25: =IFERROR(I25/H25,0) -> 0.076597765 | O25: =IFERROR(H25/G25,0) -> 0.0017609619

Sheet 설정
A1: 쿠팡 로켓 관리 설정
A3: 실원가 가중률(부가/수수료 등) | B3: 0.13
A4: 발주 목표 배수(안전재고 x 배수) | B4: 2
A5: 안전재고 비율(월평균출고 x 비율) | B5: 1.2
A6: 마진율 경고 기준 | B6: 0.2
A7: 재고일수 경고 기준(일) | B7: 14
A8: 재고일수 과다 기준(일) | B8: 90
A9: 최근월1 라벨(표기용) | B9: 26년 1월
A10: 최근월2 라벨(표기용) | B10: 26년 2월
